Workbook

Sheet 1_요약
A1: (주)모닛 5개년 사업계획 요약 (2026~2030)
A2: AIoT 스마트 기저귀 케어(MECS PRO) · 글로벌 매출 전망 기반 손익계산서 — 단위: 억원(별도 표기 제외)
A4: 시나리오 선택 ▶ | C4: S1 경영계획(100%) | F4: ← 드롭다운으로 전환(모든 시트가 연동)
A5: 시나리오 번호(계산용) | C5: =IFERROR(MATCH(C4,'8_가정'!$C$16:$E$16,0),1) -> 1
A6: 바로가기 ▶ | C6: 2_손익계산서 | E6: 10_IR정합 | G6: 9_시나리오 | I6: 6_거래처현황
A7: 핵심 지표 | C7: 2025A | D7: 2026E | E7: 2027E | F7: 2028E | G7: 2029E | H7: 2030E | I7: CAGR('25~'30)
A8: 매출액 | C8: ='3_연간손익'!C7/100000 -> 8.5416309 | D8: ='3_연간손익'!D7/100000 -> 12.01217 | E8: ='3_연간손익'!E7/100000 -> 100.05 | F8: ='3_연간손익'!F7/100000 -> 330 | G8: ='3_연간손익'!G7/100000 -> 700 | H8: ='3_연간손익'!H7/100000 -> 1560 | I8: =IFERROR(('3_연간손익'!H7/'3_연간손익'!C7)^(1/5)-1,"n/a") -> 1.8334579
A9: 전년 대비 성장률 | C9: ='3_연간손익'!C7/'3_연간손익'!B7-1 -> 0.053841471 | D9: ='3_연간손익'!D8 -> 0.40630872 | E9: ='3_연간손익'!E8 -> 7.329053 | F9: ='3_연간손익'!F8 -> 2.2983508 | G9: ='3_연간손익'!G8 -> 1.1212121 | H9: ='3_연간손익'!H8 -> 1.2285714
A10: 매출총이익 | C10: ='3_연간손익'!C10/100000 -> 4.5343539 | D10: ='3_연간손익'!D10/100000 -> 5.9961595 | E10: ='3_연간손익'!E10/100000 -> 39.792142 | F10: ='3_연간손익'!F10/100000 -> 130.8958 | G10: ='3_연간손익'!G10/100000 -> 279.72385 | H10: ='3_연간손익'!H10/100000 -> 638.35493 | I10: =IFERROR(('3_연간손익'!H10/'3_연간손익'!C10)^(1/5)-1,"n/a") -> 1.6897342
A11: 매출총이익률 | C11: ='3_연간손익'!C11 -> 0.53085341 | D11: ='3_연간손익'!D11 -> 0.49917371 | E11: ='3_연간손익'!E11 -> 0.39772256 | F11: ='3_연간손익'!F11 -> 0.39665393 | G11: ='3_연간손익'!G11 -> 0.3996055 | H11: ='3_연간손익'!H11 -> 0.40920188
A12: 영업이익 | C12: ='3_연간손익'!C13/100000 -> 0.26795791 | D12: ='3_연간손익'!D13/100000 -> 0.21957679 | E12: ='3_연간손익'!E13/100000 -> 8.7620313 | F12: ='3_연간손익'!F13/100000 -> 37.45981 | G12: ='3_연간손익'!G13/100000 -> 96.636987 | H12: ='3_연간손익'!H13/100000 -> 256.12898 | I12: =IFERROR(('3_연간손익'!H13/'3_연간손익'!C13)^(1/5)-1,"n/a") -> 2.9452854
A13: 영업이익률 | C13: ='3_연간손익'!C14 -> 0.031370813 | D13: ='3_연간손익'!D14 -> 0.018279527 | E13: ='3_연간손익'!E14 -> 0.087576525 | F13: ='3_연간손익'!F14 -> 0.11351458 | G13: ='3_연간손익'!G14 -> 0.13805284 | H13: ='3_연간손익'!H14 -> 0.16418524
A14: 당기순이익 | C14: ='3_연간손익'!C21/100000 -> 0.05167185 | D14: ='3_연간손익'!D21/100000 -> 0.41411242 | E14: ='3_연간손익'!E21/100000 -> 10.994031 | F14: ='3_연간손익'!F21/100000 -> 32.88184 | G14: ='3_연간손익'!G21/100000 -> 73.38165 | H14: ='3_연간손익'!H21/100000 -> 195.52153 | I14: =IFERROR(('3_연간손익'!H21/'3_연간손익'!C21)^(1/5)-1,"n/a") -> 4.1950306
A15: EBITDA | D15: ='3_연간손익'!D23/100000 -> 0.39957679 | E15: ='3_연간손익'!E23/100000 -> 13.121561 | F15: ='3_연간손익'!F23/100000 -> 42.740494 | G15: ='3_연간손익'!G23/100000 -> 103.53579 | H15: ='3_연간손익'!H23/100000 -> 264.93292
A16: 인원(기말, 명) | D16: ='3_연간손익'!D24 -> 7 | E16: ='3_연간손익'!E24 -> 22 | F16: ='3_연간손익'!F24 -> 85 | G16: ='3_연간손익'!G24 -> 130 | H16: ='3_연간손익'!H24 -> 260
A17: 인당 매출(백만원, 평균 인원 기준) | D17: ='3_연간손익'!D25 -> 171.60243 | E17: ='3_연간손익'!E25 -> 714.64286 | F17: ='3_연간손익'!F25 -> 616.82243 | G17: ='3_연간손익'!G25 -> 651.16279 | H17: ='3_연간손익'!H25 -> 800
A18: 추정 유료 이용자(명, 평균) | D18: ='3_연간손익'!D26 -> 934.68621 | E18: ='3_연간손익'!E26 -> 7856.9 | F18: ='3_연간손익'!F26 -> 24986.21 | G18: ='3_연간손익'!G26 -> 50165.52 | H18: ='3_연간손익'!H26 -> 105594.41
A19: IR 매출 목표 | D19: ='3_연간손익'!D27/100000 -> 12 | E19: ='3_연간손익'!E27/100000 -> 100.05 | F19: ='3_연간손익'!F27/100000 -> 330 | G19: ='3_연간손익'!G27/100000 -> 700 | H19: ='3_연간손익'!H27/100000 -> 1560
A20: IR 대비 달성률 | D20: ='3_연간손익'!D28 -> 1.0010142 | E20: ='3_연간손익'!E28 -> 1 | F20: ='3_연간손익'!F28 -> 1 | G20: ='3_연간손익'!G28 -> 1 | H20: ='3_연간손익'!H28 -> 1
A22: 지역별 매출 (억원)
A23: 지역 | D23: 2026 | E23: 2027 | F23: 2028 | G23: 2029 | H23: 2030
A24: 한국 | D24: ='3_연간손익'!D46/100000 -> 6.57067 | E24: ='3_연간손익'!E46/100000 -> 64.33 | F24: ='3_연간손익'!F46/100000 -> 117.50264 | G24: ='3_연간손익'!G46/100000 -> 170.75924 | H24: ='3_연간손익'!H46/100000 -> 220.28629
A25: 일본 | D25: ='3_연간손익'!D47/100000 -> 0 | E25: ='3_연간손익'!E47/100000 -> 4.8 | F25: ='3_연간손익'!F47/100000 -> 90.74868 | G25: ='3_연간손익'!G47/100000 -> 291.87988 | H25: ='3_연간손익'!H47/100000 -> 605.35685
A26: 동남아·APAC | D26: ='3_연간손익'!D48/100000 -> 4.04488 | E26: ='3_연간손익'!E48/100000 -> 17.924 | F26: ='3_연간손익'!F48/100000 -> 38.511855 | G26: ='3_연간손익'!G48/100000 -> 73.104353 | H26: ='3_연간손익'!H48/100000 -> 152.00008
A27: 인도 | D27: ='3_연간손익'!D49/100000 -> 0.2 | E27: ='3_연간손익'!E49/100000 -> 2 | F27: ='3_연간손익'!F49/100000 -> 4.6 | G27: ='3_연간손익'!G49/100000 -> 12.6 | H27: ='3_연간손익'!H49/100000 -> 20.6
A28: 유럽 | D28: ='3_연간손익'!D50/100000 -> 1.19662 | E28: ='3_연간손익'!E50/100000 -> 8.3976 | F28: ='3_연간손익'!F50/100000 -> 15.158922 | G28: ='3_연간손익'!G50/100000 -> 62.891245 | H28: ='3_연간손익'!H50/100000 -> 130.85224
A29: 미국 | D29: ='3_연간손익'!D51/100000 -> 0 | E29: ='3_연간손익'!E51/100000 -> 1.624 | F29: ='3_연간손익'!F51/100000 -> 37.077903 | G29: ='3_연간손익'!G51/100000 -> 46.765284 | H29: ='3_연간손익'!H51/100000 -> 352.90454
A30: 글로벌(삼성채널) | D30: ='3_연간손익'!D52/100000 -> 0 | E30: ='3_연간손익'!E52/100000 -> 0.9744 | F30: ='3_연간손익'!F52/100000 -> 26.4 | G30: ='3_연간손익'!G52/100000 -> 42 | H30: ='3_연간손익'!H52/100000 -> 78
A31: 합계 | D31: =SUM(D24:D30) -> 12.01217 | E31: =SUM(E24:E30) -> 100.05 | F31: =SUM(F24:F30) -> 330 | G31: =SUM(G24:G30) -> 700 | H31: =SUM(H24:H30) -> 1560
A33: 근거수준별 매출 비중 — 얼마나 "확정"에 기대고 있는가
A34: 근거수준 | D34: 2026 | E34: 2027 | F34: 2028 | G34: 2029 | H34: 2030
A35: A 계약·기존 거래 | D35: ='3_연간손익'!D71 -> 0.71865866 | E35: ='3_연간손익'!E71 -> 0.5713943 | F35: ='3_연간손익'!F71 -> 0.30403442 | G35: ='3_연간손익'!G71 -> 0.20603495 | H35: ='3_연간손익'!H71 -> 0.11986507
A36: B 등록·입찰·협의 단계 | D36: ='3_연간손익'!D72 -> 0.28134134 | E36: ='3_연간손익'!E72 -> 0.34744628 | F36: ='3_연간손익'!F72 -> 0.26388873 | G36: ='3_연간손익'!G72 -> 0.22180511 | H36: ='3_연간손익'!H72 -> 0.14392885
A37: C 신규 파이프라인(미확정) | D37: ='3_연간손익'!D73 -> 0 | E37: ='3_연간손익'!E73 -> 0.08115942 | F37: ='3_연간손익'!F73 -> 0.43207685 | G37: ='3_연간손익'!G73 -> 0.57215994 | H37: ='3_연간손익'!H73 -> 0.73620608
A39: 제품별 매출 (억원)
A40: 제품 | D40: 2026 | E40: 2027 | F40: 2028 | G40: 2029 | H40: 2030
A41: 스마트 기저귀(전용 기저귀·패드, 소모품) | D41: ='3_연간손익'!D32/100000 -> 7.3902742 | E41: ='3_연간손익'!E32/100000 -> 69.8895 | F41: ='3_연간손익'!F32/100000 -> 220.89683 | G41: ='3_연간손익'!G32/100000 -> 434.54751 | H41: ='3_연간손익'!H32/100000 -> 900.93769
A42: 센서·BLE 게이트웨이(하드웨어) | D42: ='3_연간손익'!D33/100000 -> 2.4697051 | E42: ='3_연간손익'!E33/100000 -> 13.8663 | F42: ='3_연간손익'!F33/100000 -> 41.107007 | G42: ='3_연간손익'!G33/100000 -> 86.362007 | H42: ='3_연간손익'!H33/100000 -> 183.03207
A43: 앱·웹 모니터링 구독(SW·AI) | D43: ='3_연간손익'!D34/100000 -> 1.3562552 | E43: ='3_연간손익'!E34/100000 -> 10.527 | F43: ='3_연간손익'!F34/100000 -> 37.83068 | G43: ='3_연간손익'!G34/100000 -> 81.076728 | H43: ='3_연간손익'!H34/100000 -> 183.16315
A44: 바이탈 모니터링 센서(60GHz, 2026 Q4 출시) | D44: ='3_연간손익'!D35/100000 -> 0 | E44: ='3_연간손익'!E35/100000 -> 2.3824 | F44: ='3_연간손익'!F35/100000 -> 17.924461 | G44: ='3_연간손익'!G35/100000 -> 59.493502 | H44: ='3_연간손익'!H35/100000 -> 177.2389
...

Sheet 2_손익계산서
A1: (주)모닛 5개년 사업계획 — 손익계산서 (2026~2030)
A2: ="단위: 천원 | 시나리오: "&'1_요약'!$C$4&" | 2026-01~09: 매출 = 거래처 매출표 실적(잠정, 비용은 추정·회계 마감 시 교체) · 2026-10부터 계획" -> 단위: 천원 | 시나리오: S1 경영계획(100%) | 2026-01~09: 매출 = 거래처 매출표 실적(잠정, 비용은 추정·회계 마감 시 교체) · 2026-10부터 계획
A5: 계정과목 | B5: 비고 | C5: 2026-01 | D5: 2026-02 | E5: 2026-03 | F5: 2026-04 | G5: 2026-05 | H5: 2026-06 | I5: 2026-07 | J5: 2026-08 | K5: 2026-09 | L5: 2026-10 | M5: 2026-11 | N5: 2026-12 | O5: FY2026 | P5: 2027-01 | Q5: 2027-02 | R5: 2027-03 | S5: 2027-04 | T5: 2027-05 | U5: 2027-06 | V5: 2027-07 | W5: 2027-08 | X5: 2027-09 | Y5: 2027-10 | Z5: 2027-11 | AA5: 2027-12 | AB5: FY2027 | AC5: 2028E | AD5: 2029E | AE5: 2030E | AF5: 5개년 합계
C6: 잠정 | D6: 잠정 | E6: 잠정 | F6: 잠정 | G6: 잠정 | H6: 잠정 | I6: 잠정 | J6: 잠정 | K6: 잠정 | L6: 계획 | M6: 계획 | N6: 계획 | O6: FY합계 | P6: 계획 | Q6: 계획 | R6: 계획 | S6: 계획 | T6: 계획 | U6: 계획 | V6: 계획 | W6: 계획 | X6: 계획 | Y6: 계획 | Z6: 계획 | AA6: 계획 | AB6: FY합계 | AC6: 계획(연) | AD6: 계획(연) | AE6: 계획(연) | AF6: 합계
A7: Ⅰ. 매출액
A8: 1. 베이비 매출 | B8: 5_매출_제품지역 G블록(카테고리 × 제품) | C8: =SUM(C9:C11) -> 7738 | D8: =SUM(D9:D11) -> 9569 | E8: =SUM(E9:E11) -> 33009 | F8: =SUM(F9:F11) -> 10450 | G8: =SUM(G9:G11) -> 21318 | H8: =SUM(H9:H11) -> 50361 | I8: =SUM(I9:I11) -> 11631 | J8: =SUM(J9:J11) -> 7239 | ... AF8: =SUM(AF9:AF11) -> 20306137
A9: 스마트 기저귀(전용 기저귀·패드, 소모품) | C9: ='5_매출_제품지역'!C61 -> 6577.3 | D9: ='5_매출_제품지역'!D61 -> 8133.65 | E9: ='5_매출_제품지역'!E61 -> 28057.65 | F9: ='5_매출_제품지역'!F61 -> 8882.5 | G9: ='5_매출_제품지역'!G61 -> 18120.3 | H9: ='5_매출_제품지역'!H61 -> 42806.85 | I9: ='5_매출_제품지역'!I61 -> 9886.35 | J9: ='5_매출_제품지역'!J61 -> 6153.15 | ... N9: ='5_매출_제품지역'!N61 -> 32895 | O9: =SUM(C9:N9) -> 199361.55 | P9: ='5_매출_제품지역'!O61 -> 140317.15 | Q9: ='5_매출_제품지역'!P61 -> 128703.6 | R9: ='5_매출_제품지역'!Q61 -> 136294.95 | S9: ='5_매출_제품지역'!R61 -> 151938.35 | T9: ='5_매출_제품지역'!S61 -> 155111.4 | U9: ='5_매출_제품지역'!T61 -> 158590.45 | V9: ='5_매출_제품지역'!U61 -> 186203.55 | W9: ='5_매출_제품지역'!V61 -> 190383.85 | ... AA9: ='5_매출_제품지역'!Z61 -> 225143.75 | AB9: =SUM(P9:AA9) -> 2100350 | AC9: ='5_매출_제품지역'!AC61 -> 3593290 | AD9: ='5_매출_제품지역'!AD61 -> 5009628 | AE9: ='5_매출_제품지역'!AE61 -> 6357586.6 | AF9: =O9+AB9+AC9+AD9+AE9 -> 17260216
A10: 센서·BLE 게이트웨이(하드웨어) | C10: ='5_매출_제품지역'!C62 -> 386.9 | D10: ='5_매출_제품지역'!D62 -> 478.45 | E10: ='5_매출_제품지역'!E62 -> 1650.45 | F10: ='5_매출_제품지역'!F62 -> 522.5 | G10: ='5_매출_제품지역'!G62 -> 1065.9 | H10: ='5_매출_제품지역'!H62 -> 2518.05 | I10: ='5_매출_제품지역'!I62 -> 581.55 | J10: ='5_매출_제품지역'!J62 -> 361.95 | ... N10: ='5_매출_제품지역'!N62 -> 1935 | O10: =SUM(C10:N10) -> 11727.15 | P10: ='5_매출_제품지역'!O62 -> 8253.95 | Q10: ='5_매출_제품지역'!P62 -> 7570.8 | R10: ='5_매출_제품지역'!Q62 -> 8017.35 | S10: ='5_매출_제품지역'!R62 -> 8937.55 | T10: ='5_매출_제품지역'!S62 -> 9124.2 | U10: ='5_매출_제품지역'!T62 -> 9328.85 | V10: ='5_매출_제품지역'!U62 -> 10953.15 | W10: ='5_매출_제품지역'!V62 -> 11199.05 | ... AA10: ='5_매출_제품지역'!Z62 -> 13243.75 | AB10: =SUM(P10:AA10) -> 123550 | AC10: ='5_매출_제품지역'!AC62 -> 211370 | AD10: ='5_매출_제품지역'!AD62 -> 294684 | AE10: ='5_매출_제품지역'!AE62 -> 373975.68 | AF10: =O10+AB10+AC10+AD10+AE10 -> 1015306.8
A11: 앱·웹 모니터링 구독(SW·AI) | C11: ='5_매출_제품지역'!C63 -> 773.8 | D11: ='5_매출_제품지역'!D63 -> 956.9 | E11: ='5_매출_제품지역'!E63 -> 3300.9 | F11: ='5_매출_제품지역'!F63 -> 1045 | G11: ='5_매출_제품지역'!G63 -> 2131.8 | H11: ='5_매출_제품지역'!H63 -> 5036.1 | I11: ='5_매출_제품지역'!I63 -> 1163.1 | J11: ='5_매출_제품지역'!J63 -> 723.9 | ... N11: ='5_매출_제품지역'!N63 -> 3870 | O11: =SUM(C11:N11) -> 23454.3 | P11: ='5_매출_제품지역'!O63 -> 16507.9 | Q11: ='5_매출_제품지역'!P63 -> 15141.6 | R11: ='5_매출_제품지역'!Q63 -> 16034.7 | S11: ='5_매출_제품지역'!R63 -> 17875.1 | T11: ='5_매출_제품지역'!S63 -> 18248.4 | U11: ='5_매출_제품지역'!T63 -> 18657.7 | V11: ='5_매출_제품지역'!U63 -> 21906.3 | W11: ='5_매출_제품지역'!V63 -> 22398.1 | ... AA11: ='5_매출_제품지역'!Z63 -> 26487.5 | AB11: =SUM(P11:AA11) -> 247100 | AC11: ='5_매출_제품지역'!AC63 -> 422740 | AD11: ='5_매출_제품지역'!AD63 -> 589368 | AE11: ='5_매출_제품지역'!AE63 -> 747951.36 | AF11: =O11+AB11+AC11+AD11+AE11 -> 2030613.7
A12: 2. 엘더리 매출 | B12: 5_매출_제품지역 G블록(카테고리 × 제품) | C12: =SUM(C13:C18) -> 39329 | D12: =SUM(D13:D18) -> 26571 | E12: =SUM(E13:E18) -> 23445 | F12: =SUM(F13:F18) -> 485 | G12: =SUM(G13:G18) -> 999 | H12: =SUM(H13:H18) -> 1092 | I12: =SUM(I13:I18) -> 1683 | J12: =SUM(J13:J18) -> 687 | ... AF12: =SUM(AF13:AF18) -> 2.4990008e+08
A13: 스마트 기저귀(전용 기저귀·패드, 소모품) | C13: ='5_매출_제품지역'!C67 -> 24732.28 | D13: ='5_매출_제품지역'!D67 -> 19466.25 | E13: ='5_매출_제품지역'!E67 -> 14359.32 | F13: ='5_매출_제품지역'!F67 -> 388 | G13: ='5_매출_제품지역'!G67 -> 799.2 | H13: ='5_매출_제품지역'!H67 -> 873.6 | I13: ='5_매출_제품지역'!I67 -> 1346.4 | J13: ='5_매출_제품지역'!J67 -> 549.6 | ... N13: ='5_매출_제품지역'!N67 -> 196504 | O13: =SUM(C13:N13) -> 539665.87 | P13: ='5_매출_제품지역'!O67 -> 223804.4 | Q13: ='5_매출_제품지역'!P67 -> 253134.7 | R13: ='5_매출_제품지역'!Q67 -> 312561.4 | S13: ='5_매출_제품지역'!R67 -> 350893.06 | T13: ='5_매출_제품지역'!S67 -> 384353.58 | U13: ='5_매출_제품지역'!T67 -> 408422.5 | V13: ='5_매출_제품지역'!U67 -> 432872.34 | W13: ='5_매출_제품지역'!V67 -> 448314.14 | ... AA13: ='5_매출_제품지역'!Z67 -> 554050.84 | AB13: =SUM(P13:AA13) -> 4888600 | AC13: ='5_매출_제품지역'!AC67 -> 18496393 | AD13: ='5_매출_제품지역'!AD67 -> 38445123 | AE13: ='5_매출_제품지역'!AE67 -> 83736183 | AF13: =O13+AB13+AC13+AD13+AE13 -> 1.4610596e+08
A14: 센서·BLE 게이트웨이(하드웨어) | C14: ='5_매출_제품지역'!C68 -> 9840.64 | D14: ='5_매출_제품지역'!D68 -> 3796.86 | E14: ='5_매출_제품지역'!E68 -> 6600 | F14: ='5_매출_제품지역'!F68 -> 38.8 | G14: ='5_매출_제품지역'!G68 -> 79.92 | H14: ='5_매출_제품지역'!H68 -> 87.36 | I14: ='5_매출_제품지역'!I68 -> 134.64 | J14: ='5_매출_제품지역'!J68 -> 54.96 | ... N14: ='5_매출_제품지역'!N68 -> 170668.3 | O14: =SUM(C14:N14) -> 235243.36 | P14: ='5_매출_제품지역'!O68 -> 46901.04 | Q14: ='5_매출_제품지역'!P68 -> 54982.16 | R14: ='5_매출_제품지역'!Q68 -> 82014.42 | S14: ='5_매출_제품지역'!R68 -> 91623.7 | T14: ='5_매출_제품지역'!S68 -> 100009.08 | U14: ='5_매출_제품지역'!T68 -> 104722.46 | V14: ='5_매출_제품지역'!U68 -> 109690.96 | W14: ='5_매출_제품지역'!V68 -> 115917.48 | ... AA14: ='5_매출_제품지역'!Z68 -> 155805.2 | AB14: =SUM(P14:AA14) -> 1263080 | AC14: ='5_매출_제품지역'!AC68 -> 3899330.7 | AD14: ='5_매출_제품지역'!AD68 -> 8341516.7 | AE14: ='5_매출_제품지역'!AE68 -> 17929231 | AF14: =O14+AB14+AC14+AD14+AE14 -> 31668402
A15: 앱·웹 모니터링 구독(SW·AI) | C15: ='5_매출_제품지역'!C69 -> 4756.08 | D15: ='5_매출_제품지역'!D69 -> 3307.89 | E15: ='5_매출_제품지역'!E69 -> 2485.68 | F15: ='5_매출_제품지역'!F69 -> 58.2 | G15: ='5_매출_제품지역'!G69 -> 119.88 | H15: ='5_매출_제품지역'!H69 -> 131.04 | I15: ='5_매출_제품지역'!I69 -> 201.96 | J15: ='5_매출_제품지역'!J69 -> 82.44 | ... N15: ='5_매출_제품지역'!N69 -> 58421.15 | O15: =SUM(C15:N15) -> 112171.22 | P15: ='5_매출_제품지역'!O69 -> 36746.2 | Q15: ='5_매출_제품지역'!P69 -> 40948.75 | R15: ='5_매출_제품지역'!Q69 -> 53301 | S15: ='5_매출_제품지역'!R69 -> 58780.87 | T15: ='5_매출_제품지역'!S69 -> 63994.71 | U15: ='5_매출_제품지역'!T69 -> 67418.35 | V15: ='5_매출_제품지역'!U69 -> 70898.53 | W15: ='5_매출_제품지역'!V69 -> 73136.83 | ... AA15: ='5_매출_제품지역'!Z69 -> 91675.18 | AB15: =SUM(P15:AA15) -> 805600 | AC15: ='5_매출_제품지역'!AC69 -> 3360328 | AD15: ='5_매출_제품지역'!AD69 -> 7518304.8 | AE15: ='5_매출_제품지역'!AE69 -> 17568364 | AF15: =O15+AB15+AC15+AD15+AE15 -> 29364768
A16: 바이탈 모니터링 센서(60GHz, 2026 Q4 출시) | C16: ='5_매출_제품지역'!C70 -> 0 | D16: ='5_매출_제품지역'!D70 -> 0 | E16: ='5_매출_제품지역'!E70 -> 0 | F16: ='5_매출_제품지역'!F70 -> 0 | G16: ='5_매출_제품지역'!G70 -> 0 | H16: ='5_매출_제품지역'!H70 -> 0 | I16: ='5_매출_제품지역'!I70 -> 0 | J16: ='5_매출_제품지역'!J70 -> 0 | ... N16: ='5_매출_제품지역'!N70 -> 0 | O16: =SUM(C16:N16) -> 0 | P16: ='5_매출_제품지역'!O70 -> 10005.96 | Q16: ='5_매출_제품지역'!P70 -> 11292.99 | R16: ='5_매출_제품지역'!Q70 -> 15135.58 | S16: ='5_매출_제품지역'!R70 -> 16787.77 | T16: ='5_매출_제품지역'!S70 -> 19100.43 | U16: ='5_매출_제품지역'!T70 -> 20096.49 | V16: ='5_매출_제품지역'!U70 -> 21113.97 | W16: ='5_매출_제품지역'!V70 -> 21853.35 | ... AA16: ='5_매출_제품지역'!Z70 -> 27261.98 | AB16: =SUM(P16:AA16) -> 238240 | AC16: ='5_매출_제품지역'!AC70 -> 1792446.1 | AD16: ='5_매출_제품지역'!AD70 -> 5949350.2 | AE16: ='5_매출_제품지역'!AE70 -> 17723890 | AF16: =O16+AB16+AC16+AD16+AE16 -> 25703926
A17: 스마트 욕창 케어(2027 출시) | C17: ='5_매출_제품지역'!C71 -> 0 | D17: ='5_매출_제품지역'!D71 -> 0 | E17: ='5_매출_제품지역'!E71 -> 0 | F17: ='5_매출_제품지역'!F71 -> 0 | G17: ='5_매출_제품지역'!G71 -> 0 | H17: ='5_매출_제품지역'!H71 -> 0 | I17: ='5_매출_제품지역'!I71 -> 0 | J17: ='5_매출_제품지역'!J71 -> 0 | ... N17: ='5_매출_제품지역'!N71 -> 0 | O17: =SUM(C17:N17) -> 0 | P17: ='5_매출_제품지역'!O71 -> 487.2 | Q17: ='5_매출_제품지역'!P71 -> 487.2 | R17: ='5_매출_제품지역'!Q71 -> 1136.8 | S17: ='5_매출_제품지역'!R71 -> 1136.8 | T17: ='5_매출_제품지역'!S71 -> 1461.6 | U17: ='5_매출_제품지역'!T71 -> 1461.6 | V17: ='5_매출_제품지역'!U71 -> 1461.6 | W17: ='5_매출_제품지역'!V71 -> 1461.6 | ... AA17: ='5_매출_제품지역'!Z71 -> 1786.4 | AB17: =SUM(P17:AA17) -> 16240 | AC17: ='5_매출_제품지역'!AC71 -> 424931.36 | AD17: ='5_매출_제품지역'!AD71 -> 2283801.6 | AE17: ='5_매출_제품지역'!AE71 -> 8282271.8 | AF17: =O17+AB17+AC17+AD17+AE17 -> 11007245
A18: R&D·PoC 용역 | C18: ='5_매출_제품지역'!C72 -> 0 | D18: ='5_매출_제품지역'!D72 -> 0 | E18: ='5_매출_제품지역'!E72 -> 0 | F18: ='5_매출_제품지역'!F72 -> 0 | G18: ='5_매출_제품지역'!G72 -> 0 | H18: ='5_매출_제품지역'!H72 -> 0 | I18: ='5_매출_제품지역'!I72 -> 0 | J18: ='5_매출_제품지역'!J72 -> 0 | ... N18: ='5_매출_제품지역'!N72 -> 28343.55 | O18: =SUM(C18:N18) -> 79593.55 | P18: ='5_매출_제품지역'!O72 -> 4987.2 | Q18: ='5_매출_제품지역'!P72 -> 5868.2 | R18: ='5_매출_제품지역'!Q72 -> 18097.8 | S18: ='5_매출_제품지역'!R72 -> 23036.8 | T18: ='5_매출_제품지역'!S72 -> 25037.6 | U18: ='5_매출_제품지역'!T72 -> 26874.6 | V18: ='5_매출_제품지역'!U72 -> 28889.6 | W18: ='5_매출_제품지역'!V72 -> 31097.6 | ... AA18: ='5_매출_제품지역'!Z72 -> 45600.4 | AB18: =SUM(P18:AA18) -> 322240 | AC18: ='5_매출_제품지역'!AC72 -> 799170.72 | AD18: ='5_매출_제품지역'!AD72 -> 1568223.9 | AE18: ='5_매출_제품지역'!AE72 -> 3280547 | AF18: =O18+AB18+AC18+AD18+AE18 -> 6049775.2
A19: 매출액(베이비 + 엘더리) | C19: =C8+C12 -> 47067 | D19: =D8+D12 -> 36140 | E19: =E8+E12 -> 56454 | F19: =F8+F12 -> 10935 | G19: =G8+G12 -> 22317 | H19: =H8+H12 -> 51453 | I19: =I8+I12 -> 13314 | J19: =J8+J12 -> 7926 | ... AF19: =AF8+AF12 -> 270206217
A20: 전년 대비 성장률 | B20: 2026은 2025A 대비 | O20: =IFERROR(O19/'3_연간손익'!$C$7-1,0) -> 0.40630872 | AB20: =IFERROR(AB19/O19-1,0) -> 7.329053 | AC20: =IFERROR(AC19/AB19-1,0) -> 2.2983508 | AD20: =IFERROR(AD19/AC19-1,0) -> 1.1212121 | AE20: =IFERROR(AE19/AD19-1,0) -> 1.2285714
A21: 베이비 매출 비중 | C21: =IFERROR(C8/C19,0) -> 0.16440393 | D21: =IFERROR(D8/D19,0) -> 0.26477587 | E21: =IFERROR(E8/E19,0) -> 0.58470613 | F21: =IFERROR(F8/F19,0) -> 0.95564701 | G21: =IFERROR(G8/G19,0) -> 0.95523592 | H21: =IFERROR(H8/H19,0) -> 0.97877675 | I21: =IFERROR(I8/I19,0) -> 0.87359171 | J21: =IFERROR(J8/J19,0) -> 0.91332324 | ... AF21: =IFERROR(AF8/AF19,0) -> 0.075150516
A22: 검증: 거래처 매출 합계(4번 시트) − 매출액 (0이어야 함) | C22: ='4_매출_거래처'!X90-C19 -> 0 | D22: ='4_매출_거래처'!Y90-D19 -> 0 | E22: ='4_매출_거래처'!Z90-E19 -> 0 | F22: ='4_매출_거래처'!AA90-F19 -> 0 | G22: ='4_매출_거래처'!AB90-G19 -> 0 | H22: ='4_매출_거래처'!AC90-H19 -> 0 | I22: ='4_매출_거래처'!AD90-I19 -> 0 | J22: ='4_매출_거래처'!AE90-J19 -> 0 | ... N22: ='4_매출_거래처'!AI90-N19 -> 0 | O22: ='4_매출_거래처'!AV90-O19 -> 0 | P22: ='4_매출_거래처'!AJ90-P19 -> 0 | Q22: ='4_매출_거래처'!AK90-Q19 -> 0 | R22: ='4_매출_거래처'!AL90-R19 -> 0 | S22: ='4_매출_거래처'!AM90-S19 -> 0 | T22: ='4_매출_거래처'!AN90-T19 -> 0 | U22: ='4_매출_거래처'!AO90-U19 -> 0 | V22: ='4_매출_거래처'!AP90-V19 -> 0 | W22: ='4_매출_거래처'!AQ90-W19 -> 0 | ... AA22: ='4_매출_거래처'!AU90-AA19 -> 0 | AB22: ='4_매출_거래처'!AW90-AB19 -> 0 | AC22: ='4_매출_거래처'!AX90-AC19 -> 0 | AD22: ='4_매출_거래처'!AY90-AD19 -> 0 | AE22: ='4_매출_거래처'!AZ90-AE19 -> 0 | AF22: ='4_매출_거래처'!BA90-AF19 -> 0
A23: 검증: 베이비 소계 − 베이비 카테고리 합계(5번 시트) (0이어야 함) | C23: =C8-'5_매출_제품지역'!C18 -> 0 | D23: =D8-'5_매출_제품지역'!D18 -> 0 | E23: =E8-'5_매출_제품지역'!E18 -> 0 | F23: =F8-'5_매출_제품지역'!F18 -> 0 | G23: =G8-'5_매출_제품지역'!G18 -> 0 | H23: =H8-'5_매출_제품지역'!H18 -> 0 | I23: =I8-'5_매출_제품지역'!I18 -> 0 | J23: =J8-'5_매출_제품지역'!J18 -> 0 | ... N23: =N8-'5_매출_제품지역'!N18 -> 0 | O23: =O8-'5_매출_제품지역'!AA18 -> 0 | P23: =P8-'5_매출_제품지역'!O18 -> 0 | Q23: =Q8-'5_매출_제품지역'!P18 -> 0 | R23: =R8-'5_매출_제품지역'!Q18 -> 0 | S23: =S8-'5_매출_제품지역'!R18 -> 0 | T23: =T8-'5_매출_제품지역'!S18 -> 0 | U23: =U8-'5_매출_제품지역'!T18 -> 0 | V23: =V8-'5_매출_제품지역'!U18 -> 0 | W23: =W8-'5_매출_제품지역'!V18 -> 0 | ... AA23: =AA8-'5_매출_제품지역'!Z18 -> 0 | AB23: =AB8-'5_매출_제품지역'!AB18 -> 0 | AC23: =AC8-'5_매출_제품지역'!AC18 -> 0 | AD23: =AD8-'5_매출_제품지역'!AD18 -> 0 | AE23: =AE8-'5_매출_제품지역'!AE18 -> 0 | AF23: =AF8-'5_매출_제품지역'!AF18 -> 0
A25: Ⅱ. 매출원가
A26: 스마트 기저귀(전용 기저귀·패드, 소모품) 원가 | B26: 제품 매출(베이비+엘더리) × 원가율 | C26: ='5_매출_제품지역'!C9*'8_가정'!$C$37 -> 16907.173 | D26: ='5_매출_제품지역'!D9*'8_가정'!$C$37 -> 14903.946 | E26: ='5_매출_제품지역'!E9*'8_가정'!$C$37 -> 22905.164 | F26: ='5_매출_제품지역'!F9*'8_가정'!$C$37 -> 5006.07 | G26: ='5_매출_제품지역'!G9*'8_가정'!$C$37 -> 10216.53 | H26: ='5_매출_제품지역'!H9*'8_가정'!$C$37 -> 23587.443 | I26: ='5_매출_제품지역'!I9*'8_가정'!$C$37 -> 6065.685 | J26: ='5_매출_제품지역'!J9*'8_가정'!$C$37 -> 3619.485 | ... N26: ='5_매출_제품지역'!N9*'8_가정'!$C$37 -> 123875.46 | O26: =SUM(C26:N26) -> 399074.81 | P26: ='5_매출_제품지역'!O9*'8_가정'!$D$37 -> 229396.58 | Q26: ='5_매출_제품지역'!P9*'8_가정'!$D$37 -> 240558.13 | R26: ='5_매출_제품지역'!Q9*'8_가정'!$D$37 -> 282779.5 | S26: ='5_매출_제품지역'!R9*'8_가정'!$D$37 -> 316783.79 | T26: ='5_매출_제품지역'!S9*'8_가정'!$D$37 -> 339862.94 | U26: ='5_매출_제품지역'!T9*'8_가정'!$D$37 -> 357218.16 | V26: ='5_매출_제품지역'!U9*'8_가정'!$D$37 -> 390017.81 | W26: ='5_매출_제품지역'!V9*'8_가정'!$D$37 -> 402379.73 | ... AA26: ='5_매출_제품지역'!Z9*'8_가정'!$D$37 -> 490892.59 | AB26: =SUM(P26:AA26) -> 4403038.5 | AC26: ='5_매출_제품지역'!AC9*'8_가정'!$E$37 -> 14026949 | AD26: ='5_매출_제품지역'!AD9*'8_가정'!$F$37 -> 27593767 | AE26: ='5_매출_제품지역'!AE9*'8_가정'!$G$37 -> 57209544 | AF26: =O26+AB26+AC26+AD26+AE26 -> 1.0363237e+08
A27: 센서·BLE 게이트웨이(하드웨어) 원가 | B27: 제품 매출(베이비+엘더리) × 원가율 | C27: ='5_매출_제품지역'!C10*'8_가정'!$C$38 -> 4704.6684 | D27: ='5_매출_제품지역'!D10*'8_가정'!$C$38 -> 1966.6426 | E27: ='5_매출_제품지역'!E10*'8_가정'!$C$38 -> 3795.207 | F27: ='5_매출_제품지역'!F10*'8_가정'!$C$38 -> 258.198 | G27: ='5_매출_제품지역'!G10*'8_가정'!$C$38 -> 527.0772 | H27: ='5_매출_제품지역'!H10*'8_가정'!$C$38 -> 1198.4886 | I27: ='5_매출_제품지역'!I10*'8_가정'!$C$38 -> 329.4474 | J27: ='5_매출_제품지역'!J10*'8_가정'!$C$38 -> 191.7786 | ... N27: ='5_매출_제품지역'!N10*'8_가정'!$C$38 -> 79397.518 | O27: =SUM(C27:N27) -> 113606.43 | P27: ='5_매출_제품지역'!O10*'8_가정'!$D$38 -> 31438.344 | Q27: ='5_매출_제품지역'!P10*'8_가정'!$D$38 -> 35655.187 | R27: ='5_매출_제품지역'!Q10*'8_가정'!$D$38 -> 51318.109 | S27: ='5_매출_제품지역'!R10*'8_가정'!$D$38 -> 57319.912 | T27: ='5_매출_제품지역'!S10*'8_가정'!$D$38 -> 62205.97 | U27: ='5_매출_제품지역'!T10*'8_가정'!$D$38 -> 65009.247 | V27: ='5_매출_제품지역'!U10*'8_가정'!$D$38 -> 68767.143 | W27: ='5_매출_제품지역'!V10*'8_가정'!$D$38 -> 72456.422 | ... AA27: ='5_매출_제품지역'!Z10*'8_가정'!$D$38 -> 96357.902 | AB27: =SUM(P27:AA27) -> 790379.1 | AC27: ='5_매출_제품지역'!AC10*'8_가정'!$E$38 -> 2301992.4 | AD27: ='5_매출_제품지역'!AD10*'8_가정'!$F$38 -> 4749910.4 | AE27: ='5_매출_제품지역'!AE10*'8_가정'!$G$38 -> 9883731.9 | AF27: =O27+AB27+AC27+AD27+AE27 -> 17839620
A28: 앱·웹 모니터링 구독(SW·AI) 원가 | B28: 제품 매출(베이비+엘더리) × 원가율 | C28: ='5_매출_제품지역'!C11*'8_가정'!$C$39 -> 1105.976 | D28: ='5_매출_제품지역'!D11*'8_가정'!$C$39 -> 852.958 | E28: ='5_매출_제품지역'!E11*'8_가정'!$C$39 -> 1157.316 | F28: ='5_매출_제품지역'!F11*'8_가정'!$C$39 -> 220.64 | G28: ='5_매출_제품지역'!G11*'8_가정'!$C$39 -> 450.336 | H28: ='5_매출_제품지역'!H11*'8_가정'!$C$39 -> 1033.428 | I28: ='5_매출_제품지역'!I11*'8_가정'!$C$39 -> 273.012 | J28: ='5_매출_제품지역'!J11*'8_가정'!$C$39 -> 161.268 | ... N28: ='5_매출_제품지역'!N11*'8_가정'!$C$39 -> 12458.23 | O28: =SUM(C28:N28) -> 27125.104 | P28: ='5_매출_제품지역'!O11*'8_가정'!$D$39 -> 12780.984 | Q28: ='5_매출_제품지역'!P11*'8_가정'!$D$39 -> 13461.684 | R28: ='5_매출_제품지역'!Q11*'8_가정'!$D$39 -> 16640.568 | S28: ='5_매출_제품지역'!R11*'8_가정'!$D$39 -> 18397.433 | T28: ='5_매출_제품지역'!S11*'8_가정'!$D$39 -> 19738.346 | U28: ='5_매출_제품지역'!T11*'8_가정'!$D$39 -> 20658.252 | V28: ='5_매출_제품지역'!U11*'8_가정'!$D$39 -> 22273.159 | W28: ='5_매출_제품지역'!V11*'8_가정'!$D$39 -> 22928.383 | ... AA28: ='5_매출_제품지역'!Z11*'8_가정'!$D$39 -> 28359.043 | AB28: =SUM(P28:AA28) -> 252648 | AC28: ='5_매출_제품지역'!AC11*'8_가정'!$E$39 -> 870105.64 | AD28: ='5_매출_제품지역'!AD11*'8_가정'!$F$39 -> 1783688 | AE28: ='5_매출_제품지역'!AE11*'8_가정'!$G$39 -> 3846426.2 | AF28: =O28+AB28+AC28+AD28+AE28 -> 6779992.9
A29: 바이탈 모니터링 센서(60GHz, 2026 Q4 출시) 원가 | B29: 제품 매출(베이비+엘더리) × 원가율 | C29: ='5_매출_제품지역'!C12*'8_가정'!$C$40 -> 0 | D29: ='5_매출_제품지역'!D12*'8_가정'!$C$40 -> 0 | E29: ='5_매출_제품지역'!E12*'8_가정'!$C$40 -> 0 | F29: ='5_매출_제품지역'!F12*'8_가정'!$C$40 -> 0 | G29: ='5_매출_제품지역'!G12*'8_가정'!$C$40 -> 0 | H29: ='5_매출_제품지역'!H12*'8_가정'!$C$40 -> 0 | I29: ='5_매출_제품지역'!I12*'8_가정'!$C$40 -> 0 | J29: ='5_매출_제품지역'!J12*'8_가정'!$C$40 -> 0 | ... N29: ='5_매출_제품지역'!N12*'8_가정'!$C$40 -> 0 | O29: =SUM(C29:N29) -> 0 | P29: ='5_매출_제품지역'!O12*'8_가정'!$D$40 -> 6003.576 | Q29: ='5_매출_제품지역'!P12*'8_가정'!$D$40 -> 6775.794 | R29: ='5_매출_제품지역'!Q12*'8_가정'!$D$40 -> 9081.348 | S29: ='5_매출_제품지역'!R12*'8_가정'!$D$40 -> 10072.662 | T29: ='5_매출_제품지역'!S12*'8_가정'!$D$40 -> 11460.258 | U29: ='5_매출_제품지역'!T12*'8_가정'!$D$40 -> 12057.894 | V29: ='5_매출_제품지역'!U12*'8_가정'!$D$40 -> 12668.382 | W29: ='5_매출_제품지역'!V12*'8_가정'!$D$40 -> 13112.01 | ... AA29: ='5_매출_제품지역'!Z12*'8_가정'!$D$40 -> 16357.188 | AB29: =SUM(P29:AA29) -> 142944 | AC29: ='5_매출_제품지역'!AC12*'8_가정'!$E$40 -> 1039618.7 | AD29: ='5_매출_제품지역'!AD12*'8_가정'!$F$40 -> 3331636.1 | AE29: ='5_매출_제품지역'!AE12*'8_가정'!$G$40 -> 9570900.4 | AF29: =O29+AB29+AC29+AD29+AE29 -> 14085099
A30: 스마트 욕창 케어(2027 출시) 원가 | B30: 제품 매출(베이비+엘더리) × 원가율 | C30: ='5_매출_제품지역'!C13*'8_가정'!$C$41 -> 0 | D30: ='5_매출_제품지역'!D13*'8_가정'!$C$41 -> 0 | E30: ='5_매출_제품지역'!E13*'8_가정'!$C$41 -> 0 | F30: ='5_매출_제품지역'!F13*'8_가정'!$C$41 -> 0 | G30: ='5_매출_제품지역'!G13*'8_가정'!$C$41 -> 0 | H30: ='5_매출_제품지역'!H13*'8_가정'!$C$41 -> 0 | I30: ='5_매출_제품지역'!I13*'8_가정'!$C$41 -> 0 | J30: ='5_매출_제품지역'!J13*'8_가정'!$C$41 -> 0 | ... N30: ='5_매출_제품지역'!N13*'8_가정'!$C$41 -> 0 | O30: =SUM(C30:N30) -> 0 | P30: ='5_매출_제품지역'!O13*'8_가정'!$D$41 -> 282.576 | Q30: ='5_매출_제품지역'!P13*'8_가정'!$D$41 -> 282.576 | R30: ='5_매출_제품지역'!Q13*'8_가정'!$D$41 -> 659.344 | S30: ='5_매출_제품지역'!R13*'8_가정'!$D$41 -> 659.344 | T30: ='5_매출_제품지역'!S13*'8_가정'!$D$41 -> 847.728 | U30: ='5_매출_제품지역'!T13*'8_가정'!$D$41 -> 847.728 | V30: ='5_매출_제품지역'!U13*'8_가정'!$D$41 -> 847.728 | W30: ='5_매출_제품지역'!V13*'8_가정'!$D$41 -> 847.728 | ... AA30: ='5_매출_제품지역'!Z13*'8_가정'!$D$41 -> 1036.112 | AB30: =SUM(P30:AA30) -> 9419.2 | AC30: ='5_매출_제품지역'!AC13*'8_가정'!$E$41 -> 242210.88 | AD30: ='5_매출_제품지역'!AD13*'8_가정'!$F$41 -> 1256090.9 | AE30: ='5_매출_제품지역'!AE13*'8_가정'!$G$41 -> 4389604 | AF30: =O30+AB30+AC30+AD30+AE30 -> 5897325
A31: R&D·PoC 용역 원가 | B31: 제품 매출(베이비+엘더리) × 원가율 | C31: ='5_매출_제품지역'!C14*'8_가정'!$C$42 -> 0 | D31: ='5_매출_제품지역'!D14*'8_가정'!$C$42 -> 0 | E31: ='5_매출_제품지역'!E14*'8_가정'!$C$42 -> 0 | F31: ='5_매출_제품지역'!F14*'8_가정'!$C$42 -> 0 | G31: ='5_매출_제품지역'!G14*'8_가정'!$C$42 -> 0 | H31: ='5_매출_제품지역'!H14*'8_가정'!$C$42 -> 0 | I31: ='5_매출_제품지역'!I14*'8_가정'!$C$42 -> 0 | J31: ='5_매출_제품지역'!J14*'8_가정'!$C$42 -> 0 | ... N31: ='5_매출_제품지역'!N14*'8_가정'!$C$42 -> 15588.952 | O31: =SUM(C31:N31) -> 43776.452 | P31: ='5_매출_제품지역'!O14*'8_가정'!$D$42 -> 2742.96 | Q31: ='5_매출_제품지역'!P14*'8_가정'!$D$42 -> 3227.51 | R31: ='5_매출_제품지역'!Q14*'8_가정'!$D$42 -> 9953.79 | S31: ='5_매출_제품지역'!R14*'8_가정'!$D$42 -> 12670.24 | T31: ='5_매출_제품지역'!S14*'8_가정'!$D$42 -> 13770.68 | U31: ='5_매출_제품지역'!T14*'8_가정'!$D$42 -> 14781.03 | V31: ='5_매출_제품지역'!U14*'8_가정'!$D$42 -> 15889.28 | W31: ='5_매출_제품지역'!V14*'8_가정'!$D$42 -> 17103.68 | ... AA31: ='5_매출_제품지역'!Z14*'8_가정'!$D$42 -> 25080.22 | AB31: =SUM(P31:AA31) -> 177232 | AC31: ='5_매출_제품지역'!AC14*'8_가정'!$E$42 -> 439543.9 | AD31: ='5_매출_제품지역'!AD14*'8_가정'!$F$42 -> 862523.16 | AE31: ='5_매출_제품지역'!AE14*'8_가정'!$G$42 -> 1804300.8 | AF31: =O31+AB31+AC31+AD31+AE31 -> 3327376.3
A32: 운영성 매출원가 | B32: 물류·관세·보증·클라우드 | C32: =C19*'8_가정'!$C$43 -> 706.005 | D32: =D19*'8_가정'!$C$43 -> 542.1 | E32: =E19*'8_가정'!$C$43 -> 846.81 | F32: =F19*'8_가정'!$C$43 -> 164.025 | G32: =G19*'8_가정'!$C$43 -> 334.755 | H32: =H19*'8_가정'!$C$43 -> 771.795 | I32: =I19*'8_가정'!$C$43 -> 199.71 | J32: =J19*'8_가정'!$C$43 -> 118.89 | ... N32: =N19*'8_가정'!$C$43 -> 7389.555 | O32: =SUM(C32:N32) -> 18018.255 | P32: =P19*'8_가정'!$D$43 -> 12200.275 | Q32: =Q19*'8_가정'!$D$43 -> 12953.25 | R32: =R19*'8_가정'!$D$43 -> 16064.85 | S32: =S19*'8_가정'!$D$43 -> 18025.25 | T32: =T19*'8_가정'!$D$43 -> 19411.025 | U32: =U19*'8_가정'!$D$43 -> 20389.325 | V32: =V19*'8_가정'!$D$43 -> 22099.75 | W32: =W19*'8_가정'!$D$43 -> 22894.05 | ... AA32: =AA19*'8_가정'!$D$43 -> 28526.375 | AB32: =SUM(P32:AA32) -> 250125 | AC32: =AC19*'8_가정'!$E$43 -> 990000 | AD32: =AD19*'8_가정'!$F$43 -> 2450000 | AE32: =AE19*'8_가정'!$G$43 -> 5460000 | AF32: =O32+AB32+AC32+AD32+AE32 -> 9168143.3
A33: 매출원가 | C33: =SUM(C26:C32) -> 23423.823 | D33: =SUM(D26:D32) -> 18265.647 | E33: =SUM(E26:E32) -> 28704.497 | F33: =SUM(F26:F32) -> 5648.933 | G33: =SUM(G26:G32) -> 11528.698 | H33: =SUM(H26:H32) -> 26591.155 | I33: =SUM(I26:I32) -> 6867.8544 | J33: =SUM(J26:J32) -> 4091.4216 | ... AF33: =SUM(AF26:AF32) -> 1.6072993e+08
A34: 매출총이익 | C34: =C19-C33 -> 23643.177 | D34: =D19-D33 -> 17874.353 | E34: =E19-E33 -> 27749.503 | F34: =F19-F33 -> 5286.067 | G34: =G19-G33 -> 10788.302 | H34: =H19-H33 -> 24861.845 | I34: =I19-I33 -> 6446.1456 | J34: =J19-J33 -> 3834.5784 | ... AF34: =AF19-AF33 -> 1.0947629e+08
A35: 매출총이익률 | C35: =IFERROR(C34/C19,0) -> 0.50233024 | D35: =IFERROR(D34/D19,0) -> 0.49458643 | E35: =IFERROR(E34/E19,0) -> 0.49154184 | F35: =IFERROR(F34/F19,0) -> 0.48340805 | G35: =IFERROR(G34/G19,0) -> 0.48341183 | H35: =IFERROR(H34/H19,0) -> 0.48319525 | I35: =IFERROR(I34/I19,0) -> 0.48416296 | J35: =IFERROR(J34/J19,0) -> 0.48379743 | ... AF35: =IFERROR(AF34/AF19,0) -> 0.40515829
A37: Ⅲ. 판매비와관리비
A38: 급여 | B38: 개발비 자본화(8_가정) 차감 후 — 7_비용인력 31·61행 | C38: ='7_비용인력'!C19 -> 23833.8 | D38: ='7_비용인력'!D19 -> 23833.8 | E38: ='7_비용인력'!E19 -> 23833.8 | F38: ='7_비용인력'!F19 -> 23833.8 | G38: ='7_비용인력'!G19 -> 23833.8 | H38: ='7_비용인력'!H19 -> 23833.8 | I38: ='7_비용인력'!I19 -> 23833.8 | J38: ='7_비용인력'!J19 -> 23833.8 | ... AF38: ='7_비용인력'!AF19 -> 18960469
A39: 퇴직급여·4대보험·복리후생 | B39: 개발비 자본화(8_가정) 차감 후 — 7_비용인력 31·61행 | C39: ='7_비용인력'!C20 -> 5243.436 | D39: ='7_비용인력'!D20 -> 5243.436 | E39: ='7_비용인력'!E20 -> 5243.436 | F39: ='7_비용인력'!F20 -> 5243.436 | G39: ='7_비용인력'!G20 -> 5243.436 | H39: ='7_비용인력'!H20 -> 5243.436 | I39: ='7_비용인력'!I20 -> 5243.436 | J39: ='7_비용인력'!J20 -> 5243.436 | ... AF39: ='7_비용인력'!AF20 -> 4171303.2
A40: 광고선전·마케팅비 | C40: ='7_비용인력'!C21 -> 564.804 | D40: ='7_비용인력'!D21 -> 433.68 | E40: ='7_비용인력'!E21 -> 677.448 | F40: ='7_비용인력'!F21 -> 131.22 | G40: ='7_비용인력'!G21 -> 267.804 | H40: ='7_비용인력'!H21 -> 617.436 | I40: ='7_비용인력'!I21 -> 159.768 | J40: ='7_비용인력'!J21 -> 95.112 | ... AF40: ='7_비용인력'!AF21 -> 7688539.6
A41: 지급수수료 | C41: ='7_비용인력'!C22 -> 564.804 | D41: ='7_비용인력'!D22 -> 433.68 | E41: ='7_비용인력'!E22 -> 677.448 | F41: ='7_비용인력'!F22 -> 131.22 | G41: ='7_비용인력'!G22 -> 267.804 | H41: ='7_비용인력'!H22 -> 617.436 | I41: ='7_비용인력'!I22 -> 159.768 | J41: ='7_비용인력'!J22 -> 95.112 | ... AF41: ='7_비용인력'!AF22 -> 5912514.6
A42: 판매물류·CS비 | C42: ='7_비용인력'!C23 -> 1176.675 | D42: ='7_비용인력'!D23 -> 903.5 | E42: ='7_비용인력'!E23 -> 1411.35 | F42: ='7_비용인력'!F23 -> 273.375 | G42: ='7_비용인력'!G23 -> 557.925 | H42: ='7_비용인력'!H23 -> 1286.325 | I42: ='7_비용인력'!I23 -> 332.85 | J42: ='7_비용인력'!J23 -> 198.15 | ... AF42: ='7_비용인력'!AF23 -> 9235205.4
A43: 연구개발비(경상) | C43: ='7_비용인력'!C24 -> 1647.345 | D43: ='7_비용인력'!D24 -> 1264.9 | E43: ='7_비용인력'!E24 -> 1975.89 | F43: ='7_비용인력'!F24 -> 382.725 | G43: ='7_비용인력'!G24 -> 781.095 | H43: ='7_비용인력'!H24 -> 1800.855 | I43: ='7_비용인력'!I24 -> 465.99 | J43: ='7_비용인력'!J24 -> 277.41 | ... AF43: ='7_비용인력'!AF24 -> 8314217.6
A44: 임차·운영비 | C44: ='7_비용인력'!C25 -> 3000 | D44: ='7_비용인력'!D25 -> 3000 | E44: ='7_비용인력'!E25 -> 3000 | F44: ='7_비용인력'!F25 -> 3000 | G44: ='7_비용인력'!G25 -> 3000 | H44: ='7_비용인력'!H25 -> 3000 | I44: ='7_비용인력'!I25 -> 3000 | J44: ='7_비용인력'!J25 -> 3000 | ... AF44: ='7_비용인력'!AF25 -> 2080000
...

Sheet 3_연간손익
A1: 3_연간손익 — 2024A~2030E 연간 요약
A2: 단위: 천원. 2024·2025 = 투자사 양식 IS(2025 감사보고서, 효림회계법인 적정의견), 2026E~ = 손익계산서 시트(선택 시나리오).
A5: 구분 | B5: 2024A | C5: 2025A | D5: 2026E | E5: 2027E | F5: 2028E | G5: 2029E | H5: 2030E | I5: CAGR('25~'30)
B6: 실적 | C6: 실적 | D6: 잠정+계획 | E6: 계획 | F6: 계획 | G6: 계획 | H6: 계획
A7: 매출액 | B7: 810523.32 | C7: 854163.09 | D7: ='2_손익계산서'!O19 -> 1201217 | E7: ='2_손익계산서'!AB19 -> 10005000 | F7: ='2_손익계산서'!AC19 -> 33000000 | G7: ='2_손익계산서'!AD19 -> 70000000 | H7: ='2_손익계산서'!AE19 -> 156000000 | I7: =IFERROR((H7/C7)^(1/5)-1,"n/a") -> 1.8334579
A8: 전년 대비 성장률 | C8: =C7/B7-1 -> 0.053841471 | D8: =IFERROR(D7/C7-1,0) -> 0.40630872 | E8: =IFERROR(E7/D7-1,0) -> 7.329053 | F8: =IFERROR(F7/E7-1,0) -> 2.2983508 | G8: =IFERROR(G7/F7-1,0) -> 1.1212121 | H8: =IFERROR(H7/G7-1,0) -> 1.2285714
A9: 매출원가 | B9: 333442.72 | C9: 400727.7 | D9: ='2_손익계산서'!O33 -> 601601.05 | E9: ='2_손익계산서'!AB33 -> 6025785.8 | F9: ='2_손익계산서'!AC33 -> 19910420 | G9: ='2_손익계산서'!AD33 -> 42027615 | H9: ='2_손익계산서'!AE33 -> 92164507
A10: 매출총이익 | B10: =B7-B9 -> 477080.61 | C10: =C7-C9 -> 453435.39 | D10: =D7-D9 -> 599615.95 | E10: =E7-E9 -> 3979214.2 | F10: =F7-F9 -> 13089580 | G10: =G7-G9 -> 27972385 | H10: =H7-H9 -> 63835493 | I10: =IFERROR((H10/C10)^(1/5)-1,"n/a") -> 1.6897342
A11: 매출총이익률 | B11: =IFERROR(B10/B7,0) -> 0.58860812 | C11: =IFERROR(C10/C7,0) -> 0.53085341 | D11: =IFERROR(D10/D7,0) -> 0.49917371 | E11: =IFERROR(E10/E7,0) -> 0.39772256 | F11: =IFERROR(F10/F7,0) -> 0.39665393 | G11: =IFERROR(G10/G7,0) -> 0.3996055 | H11: =IFERROR(H10/H7,0) -> 0.40920188
A12: 판매비와관리비 | B12: 506844.64 | C12: 426639.6 | D12: ='2_손익계산서'!O49 -> 577658.27 | E12: ='2_손익계산서'!AB49 -> 3103011.1 | F12: ='2_손익계산서'!AC49 -> 9343598.7 | G12: ='2_손익계산서'!AD49 -> 18308686 | H12: ='2_손익계산서'!AE49 -> 38222595
A13: 영업이익(손실) | B13: =B10-B12 -> -29764.036 | C13: =C10-C12 -> 26795.791 | D13: =D10-D12 -> 21957.679 | E13: =E10-E12 -> 876203.13 | F13: =F10-F12 -> 3745981 | G13: =G10-G12 -> 9663698.7 | H13: =H10-H12 -> 25612898 | I13: =IFERROR((H13/C13)^(1/5)-1,"n/a") -> 2.9452854
A14: 영업이익률 | B14: =IFERROR(B13/B7,0) -> -0.036721998 | C14: =IFERROR(C13/C7,0) -> 0.031370813 | D14: =IFERROR(D13/D7,0) -> 0.018279527 | E14: =IFERROR(E13/E7,0) -> 0.087576525 | F14: =IFERROR(F13/F7,0) -> 0.11351458 | G14: =IFERROR(G13/G7,0) -> 0.13805284 | H14: =IFERROR(H13/H7,0) -> 0.16418524
A15: 영업외수익 | B15: 99422.6 | C15: 35830.08 | D15: ='2_손익계산서'!O54 -> 77042.595 | E15: ='2_손익계산서'!AB54 -> 300000 | F15: ='2_손익계산서'!AC54 -> 100000 | G15: ='2_손익계산서'!AD54 -> 100000 | H15: ='2_손익계산서'!AE54 -> 100000
A16: (정부보조금수익) | B16: 88251.938 | C16: 30520.905 | D16: ='2_손익계산서'!O55 -> 77042.595 | E16: ='2_손익계산서'!AB55 -> 300000 | F16: ='2_손익계산서'!AC55 -> 100000 | G16: ='2_손익계산서'!AD55 -> 100000 | H16: ='2_손익계산서'!AE55 -> 100000
A17: 영업외비용 | B17: 62966.483 | C17: 57458.686 | D17: ='2_손익계산서'!O56 -> 57589.032 | E17: ='2_손익계산서'!AB56 -> 76800 | F17: ='2_손익계산서'!AC56 -> 192000 | G17: ='2_손익계산서'!AD56 -> 384000 | H17: ='2_손익계산서'!AE56 -> 528000
A18: (이자비용) | B18: 47544.865 | C18: 49788.161 | D18: ='2_손익계산서'!O57 -> 57589.032 | E18: ='2_손익계산서'!AB57 -> 76800 | F18: ='2_손익계산서'!AC57 -> 192000 | G18: ='2_손익계산서'!AD57 -> 384000 | H18: ='2_손익계산서'!AE57 -> 528000
A19: 법인세차감전순이익 | B19: =B13+B15-B17 -> 6692.081 | C19: =C13+C15-C17 -> 5167.185 | D19: =D13+D15-D17 -> 41411.242 | E19: =E13+E15-E17 -> 1099403.1 | F19: =F13+F15-F17 -> 3653981 | G19: =G13+G15-G17 -> 9379698.7 | H19: =H13+H15-H17 -> 25184898
A20: 법인세등 | B20: 0 | C20: 0 | D20: ='2_손익계산서'!O59 -> 0 | E20: ='2_손익계산서'!AB59 -> 0 | F20: ='2_손익계산서'!AC59 -> 365796.94 | G20: ='2_손익계산서'!AD59 -> 2041533.7 | H20: ='2_손익계산서'!AE59 -> 5632745.3
A21: 당기순이익(손실) | B21: =B19-B20 -> 6692.081 | C21: =C19-C20 -> 5167.185 | D21: =D19-D20 -> 41411.242 | E21: =E19-E20 -> 1099403.1 | F21: =F19-F20 -> 3288184 | G21: =G19-G20 -> 7338165 | H21: =H19-H20 -> 19552153 | I21: =IFERROR((H21/C21)^(1/5)-1,"n/a") -> 4.1950306
A22: 순이익률 | B22: =IFERROR(B21/B7,0) -> 0.0082564941 | C22: =IFERROR(C21/C7,0) -> 0.0060494126 | D22: =IFERROR(D21/D7,0) -> 0.034474406 | E22: =IFERROR(E21/E7,0) -> 0.10988537 | F22: =IFERROR(F21/F7,0) -> 0.099641941 | G22: =IFERROR(G21/G7,0) -> 0.10483093 | H22: =IFERROR(H21/H7,0) -> 0.12533431
A23: EBITDA | D23: ='2_손익계산서'!O64 -> 39957.679 | E23: ='2_손익계산서'!AB64 -> 1312156.1 | F23: ='2_손익계산서'!AC64 -> 4274049.4 | G23: ='2_손익계산서'!AD64 -> 10353579 | H23: ='2_손익계산서'!AE64 -> 26493292
A24: 인원(기말, 명) | D24: ='2_손익계산서'!O66 -> 7 | E24: ='2_손익계산서'!AB66 -> 22 | F24: ='2_손익계산서'!AC66 -> 85 | G24: ='2_손익계산서'!AD66 -> 130 | H24: ='2_손익계산서'!AE66 -> 260
A25: 인당 매출(백만원, 평균 인원 기준) | D25: ='2_손익계산서'!O67 -> 171.60243 | E25: ='2_손익계산서'!AB67 -> 714.64286 | F25: ='2_손익계산서'!AC67 -> 616.82243 | G25: ='2_손익계산서'!AD67 -> 651.16279 | H25: ='2_손익계산서'!AE67 -> 800
A26: 추정 유료 이용자(명, 평균) | D26: ='2_손익계산서'!O68 -> 934.68621 | E26: ='2_손익계산서'!AB68 -> 7856.9 | F26: ='2_손익계산서'!AC68 -> 24986.21 | G26: ='2_손익계산서'!AD68 -> 50165.52 | H26: ='2_손익계산서'!AE68 -> 105594.41
A27: IR 매출 목표 | D27: ='8_가정'!$C$6 -> 1200000 | E27: ='8_가정'!$D$6 -> 10005000 | F27: ='8_가정'!$E$6 -> 33000000 | G27: ='8_가정'!$F$6 -> 70000000 | H27: ='8_가정'!$G$6 -> 156000000
A28: IR 대비 달성률 | D28: =IFERROR(D7/D27,0) -> 1.0010142 | E28: =IFERROR(E7/E27,0) -> 1 | F28: =IFERROR(F7/F27,0) -> 1 | G28: =IFERROR(G7/G27,0) -> 1 | H28: =IFERROR(H7/H27,0) -> 1
A29: 검증: 당기순이익 − 손익계산서(0이어야 함) | D29: =D21-'2_손익계산서'!O60 -> 0 | E29: =E21-'2_손익계산서'!AB60 -> 0 | F29: =F21-'2_손익계산서'!AC60 -> 0 | G29: =G21-'2_손익계산서'!AD60 -> 0 | H29: =H21-'2_손익계산서'!AE60 -> 0
A30: 검증: 제품·카테고리·지역·채널·근거수준 합계 − 매출액(0이어야 함) | D30: =ABS(D38-D7)+ABS(D43-D7)+ABS(D53-D7)+ABS(D64-D7)+ABS(D70-D7) -> 0 | E30: =ABS(E38-E7)+ABS(E43-E7)+ABS(E53-E7)+ABS(E64-E7)+ABS(E70-E7) -> 0 | F30: =ABS(F38-F7)+ABS(F43-F7)+ABS(F53-F7)+ABS(F64-F7)+ABS(F70-F7) -> 0 | G30: =ABS(G38-G7)+ABS(G43-G7)+ABS(G53-G7)+ABS(G64-G7)+ABS(G70-G7) -> 0 | H30: =ABS(H38-H7)+ABS(H43-H7)+ABS(H53-H7)+ABS(H64-H7)+ABS(H70-H7) -> 0
A31: 제품별 매출
A32: 스마트 기저귀(전용 기저귀·패드, 소모품) | D32: ='5_매출_제품지역'!AA9 -> 739027.42 | E32: ='5_매출_제품지역'!AB9 -> 6988950 | F32: ='5_매출_제품지역'!AC9 -> 22089683 | G32: ='5_매출_제품지역'!AD9 -> 43454751 | H32: ='5_매출_제품지역'!AE9 -> 90093769
A33: 센서·BLE 게이트웨이(하드웨어) | D33: ='5_매출_제품지역'!AA10 -> 246970.51 | E33: ='5_매출_제품지역'!AB10 -> 1386630 | F33: ='5_매출_제품지역'!AC10 -> 4110700.7 | G33: ='5_매출_제품지역'!AD10 -> 8636200.7 | H33: ='5_매출_제품지역'!AE10 -> 18303207
A34: 앱·웹 모니터링 구독(SW·AI) | D34: ='5_매출_제품지역'!AA11 -> 135625.52 | E34: ='5_매출_제품지역'!AB11 -> 1052700 | F34: ='5_매출_제품지역'!AC11 -> 3783068 | G34: ='5_매출_제품지역'!AD11 -> 8107672.8 | H34: ='5_매출_제품지역'!AE11 -> 18316315
A35: 바이탈 모니터링 센서(60GHz, 2026 Q4 출시) | D35: ='5_매출_제품지역'!AA12 -> 0 | E35: ='5_매출_제품지역'!AB12 -> 238240 | F35: ='5_매출_제품지역'!AC12 -> 1792446.1 | G35: ='5_매출_제품지역'!AD12 -> 5949350.2 | H35: ='5_매출_제품지역'!AE12 -> 17723890
A36: 스마트 욕창 케어(2027 출시) | D36: ='5_매출_제품지역'!AA13 -> 0 | E36: ='5_매출_제품지역'!AB13 -> 16240 | F36: ='5_매출_제품지역'!AC13 -> 424931.36 | G36: ='5_매출_제품지역'!AD13 -> 2283801.6 | H36: ='5_매출_제품지역'!AE13 -> 8282271.8
A37: R&D·PoC 용역 | D37: ='5_매출_제품지역'!AA14 -> 79593.55 | E37: ='5_매출_제품지역'!AB14 -> 322240 | F37: ='5_매출_제품지역'!AC14 -> 799170.72 | G37: ='5_매출_제품지역'!AD14 -> 1568223.9 | H37: ='5_매출_제품지역'!AE14 -> 3280547
A38: 합계 | D38: =SUM(D32:D37) -> 1201217 | E38: =SUM(E32:E37) -> 10005000 | F38: =SUM(F32:F37) -> 33000000 | G38: =SUM(G32:G37) -> 70000000 | H38: =SUM(H32:H37) -> 156000000
A40: 카테고리별 매출(베이비 / 엘더리)
A41: 베이비 | D41: ='5_매출_제품지역'!AA18 -> 234543 | E41: ='5_매출_제품지역'!AB18 -> 2471000 | F41: ='5_매출_제품지역'!AC18 -> 4227400 | G41: ='5_매출_제품지역'!AD18 -> 5893680 | H41: ='5_매출_제품지역'!AE18 -> 7479513.6
A42: 엘더리 | D42: ='5_매출_제품지역'!AA19 -> 966674 | E42: ='5_매출_제품지역'!AB19 -> 7534000 | F42: ='5_매출_제품지역'!AC19 -> 28772600 | G42: ='5_매출_제품지역'!AD19 -> 64106320 | H42: ='5_매출_제품지역'!AE19 -> 1.4852049e+08
A43: 합계 | D43: =SUM(D41:D42) -> 1201217 | E43: =SUM(E41:E42) -> 10005000 | F43: =SUM(F41:F42) -> 33000000 | G43: =SUM(G41:G42) -> 70000000 | H43: =SUM(H41:H42) -> 156000000
...

Sheet 4_매출_거래처
A1: 4_매출_거래처 — 거래처별 월별(2026~27)·연간(2028~30) 매출
A2: 단위: 천원. A블록=경영계획(S1, 입력) / B블록=선택 시나리오 적용(손익계산서·5번 시트 연동). 파란색 = 입력(2026-01~09 = 실적, 10~12월 = 확정·예상 발주, 2027 = IR 목표 기준 계획).
A3: ="현재 선택: "&'1_요약'!$C$4&" | 입력방식 M=월별 입력 + 2028~30 성장률 · N=월별 입력 + 2028~30 연간 입력 · C=신규 파이프라인(2028~30 = 지역 목표 − 지정 거래처, 8_가정 §2b) · S=삼성 글로벌 채널(IR − 타 행)" -> 현재 선택: S1 경영계획(100%) | 입력방식 M=월별 입력 + 2028~30 성장률 · N=월별 입력 + 2028~30 연간 입력 · C=신규 파이프라인(2028~30 = 지역 목표 − 지정 거래처, 8_가정 §2b) · S=삼성 글로벌 채널(IR − 타 행)
W5: 연도 | X5: 2026 | Y5: 2026 | Z5: 2026 | AA5: 2026 | AB5: 2026 | AC5: 2026 | AD5: 2026 | AE5: 2026 | AF5: 2026 | AG5: 2026 | AH5: 2026 | AI5: 2026 | AJ5: 2027 | AK5: 2027 | AL5: 2027 | AM5: 2027 | AN5: 2027 | AO5: 2027 | AP5: 2027 | AQ5: 2027 | AR5: 2027 | AS5: 2027 | AT5: 2027 | AU5: 2027
W6: 월 인덱스(1=2026-01) | X6: 1 | Y6: 2 | Z6: 3 | AA6: 4 | AB6: 5 | AC6: 6 | AD6: 7 | AE6: 8 | AF6: 9 | AG6: 10 | AH6: 11 | AI6: 12 | AJ6: 13 | AK6: 14 | AL6: 15 | AM6: 16 | AN6: 17 | AO6: 18 | AP6: 19 | AQ6: 20 | AR6: 21 | AS6: 22 | AT6: 23 | AU6: 24 | AV6: 2026 | AW6: 2027 | AX6: 2028 | AY6: 2029 | AZ6: 2030
A7: No | B7: 국가 | C7: 지역 | D7: 거래처 | E7: 카테고리 | F7: 거래형태 | G7: 모델 단계 | H7: 근거수준 | I7: 믹스 | J7: 입력방식 | K7: 2027 매출 | L7: 2028 성장 | M7: 2029 성장 | N7: 2030 성장 | V7: 근거 · 가정 | X7: 2026-01 | Y7: 2026-02 | Z7: 2026-03 | AA7: 2026-04 | AB7: 2026-05 | AC7: 2026-06 | AD7: 2026-07 | AE7: 2026-08 | AF7: 2026-09 | AG7: 2026-10 | AH7: 2026-11 | AI7: 2026-12 | AJ7: 2027-01 | AK7: 2027-02 | AL7: 2027-03 | AM7: 2027-04 | AN7: 2027-05 | AO7: 2027-06 | AP7: 2027-07 | AQ7: 2027-08 | AR7: 2027-09 | AS7: 2027-10 | AT7: 2027-11 | AU7: 2027-12 | AV7: FY2026 | AW7: FY2027 | AX7: 2028E | AY7: 2029E | AZ7: 2030E | BA7: 5개년 합계
A9: A. 경영계획(S1) — 거래처별 매출 입력
A10: 1 | B10: 한국 | C10: 한국 | D10: 네이버(Bebefit/Monit) — 베이비 | E10: 베이비 | F10: 온라인·B2C | G10: 기존 | H10: A 계약·기존 거래 | I10: BABY | J10: M | K10: =AW10 -> 195000 | L10: 0.4 | M10: 0.2 | N10: 0.12 | V10: 거래처 매출표 | X10: 2371 | Y10: 1579 | Z10: 2546 | AA10: 3668 | AB10: 1798 | AC10: 1795 | AD10: 2955 | AE10: 1587 | AF10: 1879 | AG10: 2500 | AH10: 2500 | AI10: 2500 | AJ10: 5000 | AK10: 5000 | AL10: 5000 | AM10: 10000 | AN10: 10000 | AO10: 10000 | AP10: 20000 | AQ10: 20000 | AR10: 20000 | AS10: 30000 | AT10: 30000 | AU10: 30000 | AV10: =SUM(X10:AI10) -> 27678 | AW10: =SUM(AJ10:AU10) -> 195000 | AX10: =$K10*(1+$L10) -> 273000 | AY10: =AX10*(1+$M10) -> 327600 | AZ10: =AY10*(1+$N10) -> 366912 | BA10: =SUM(AV10:AZ10) -> 1190190
A11: 2 | B11: 한국 | C11: 한국 | D11: 네이버(위탁상품) — 베이비 | E11: 베이비 | F11: 온라인·B2C | G11: 기존 | H11: A 계약·기존 거래 | I11: BABY | J11: M | K11: =AW11 -> 120000 | L11: 0.4 | M11: 0.2 | N11: 0.12 | V11: 거래처 매출표 | X11: 437 | Y11: 655 | Z11: 1002 | AA11: 735 | AB11: 721 | AC11: 498 | AD11: 835 | AE11: 473 | AF11: 1046 | AG11: 700 | AH11: 700 | AI11: 700 | AJ11: 10000 | AK11: 10000 | AL11: 10000 | AM11: 10000 | AN11: 10000 | AO11: 10000 | AP11: 10000 | AQ11: 10000 | AR11: 10000 | AS11: 10000 | AT11: 10000 | AU11: 10000 | AV11: =SUM(X11:AI11) -> 8502 | AW11: =SUM(AJ11:AU11) -> 120000 | AX11: =$K11*(1+$L11) -> 168000 | AY11: =AX11*(1+$M11) -> 201600 | AZ11: =AY11*(1+$N11) -> 225792 | BA11: =SUM(AV11:AZ11) -> 723894
A12: 3 | B12: 한국 | C12: 한국 | D12: 쿠팡 — 베이비 | E12: 베이비 | F12: 온라인·B2C | G12: 기존 | H12: A 계약·기존 거래 | I12: BABY | J12: M | K12: =AW12 -> 165000 | L12: 0.4 | M12: 0.2 | N12: 0.12 | V12: 거래처 매출표 | X12: 2678 | Y12: 3941 | Z12: 4603 | AA12: 3442 | AB12: 1575 | AC12: 7345 | AD12: 3789 | AE12: 3603 | AF12: 2983 | AG12: 3000 | AH12: 3000 | AI12: 3000 | AJ12: 5000 | AK12: 5000 | AL12: 5000 | AM12: 10000 | AN12: 10000 | AO12: 10000 | AP12: 20000 | AQ12: 20000 | AR12: 20000 | AS12: 20000 | AT12: 20000 | AU12: 20000 | AV12: =SUM(X12:AI12) -> 42959 | AW12: =SUM(AJ12:AU12) -> 165000 | AX12: =$K12*(1+$L12) -> 231000 | AY12: =AX12*(1+$M12) -> 277200 | AZ12: =AY12*(1+$N12) -> 310464 | BA12: =SUM(AV12:AZ12) -> 1026623
A13: 4 | B13: 한국 | C13: 한국 | D13: 기타 B2C — 베이비 | E13: 베이비 | F13: 온라인·B2C | G13: 기존 | H13: A 계약·기존 거래 | I13: BABY | J13: M | K13: =AW13 -> 171000 | L13: 0.4 | M13: 0.2 | N13: 0.12 | V13: 거래처 매출표 | X13: 2252 | Y13: 3394 | Z13: 2263 | AA13: 2605 | AB13: 2220 | AC13: 1490 | AD13: 4052 | AE13: 1576 | AF13: 1220 | AG13: 2500 | AH13: 2500 | AI13: 2500 | AJ13: 5000 | AK13: 5000 | AL13: 5000 | AM13: 10000 | AN13: 10000 | AO13: 10000 | AP13: 18000 | AQ13: 18000 | AR13: 18000 | AS13: 24000 | AT13: 24000 | AU13: 24000 | AV13: =SUM(X13:AI13) -> 28572 | AW13: =SUM(AJ13:AU13) -> 171000 | AX13: =$K13*(1+$L13) -> 239400 | AY13: =AX13*(1+$M13) -> 287280 | AZ13: =AY13*(1+$N13) -> 321753.6 | BA13: =SUM(AV13:AZ13) -> 1048005.6
A14: 5 | B14: 한국 | C14: 한국 | D14: B2B(국내) — 베이비 | E14: 베이비 | F14: 국내 B2B | G14: 기존 | H14: A 계약·기존 거래 | I14: BABY | J14: M | K14: =AW14 -> 220000 | L14: 0.4 | M14: 0.2 | N14: 0.12 | V14: 거래처 매출표 | X14: 0 | Y14: 0 | Z14: 0 | AA14: 0 | AB14: 0 | AC14: 0 | AD14: 0 | AE14: 0 | AF14: 0 | AG14: 0 | AH14: 0 | AI14: 10000 | AJ14: 10517 | AK14: 11531 | AL14: 12641 | AM14: 13859 | AN14: 15194 | AO14: 16657 | AP14: 18262 | AQ14: 20021 | AR14: 21949 | AS14: 24064 | AT14: 26382 | AU14: 28923 | AV14: =SUM(X14:AI14) -> 10000 | AW14: =SUM(AJ14:AU14) -> 220000 | AX14: =$K14*(1+$L14) -> 308000 | AY14: =AX14*(1+$M14) -> 369600 | AZ14: =AY14*(1+$N14) -> 413952 | BA14: =SUM(AV14:AZ14) -> 1321552
A15: 6 | B15: 한국 | C15: 한국 | D15: APP KOREA — 유아(스마트 베이비 기저귀) | E15: 베이비 | F15: 파트너 | G15: 계약 | H15: A 계약·기존 거래 | I15: BABY | J15: M | K15: =AW15 -> 1200000 | L15: 0.64 | M15: 0.3 | N15: 0.2 | V15: 거래처 매출표 · IR p.12 APP 베이비 협업 | X15: 0 | Y15: 0 | Z15: 0 | AA15: 0 | AB15: 0 | AC15: 0 | AD15: 0 | AE15: 0 | AF15: 0 | AG15: 0 | AH15: 0 | AI15: 0 | AJ15: 100000 | AK15: 100000 | AL15: 100000 | AM15: 100000 | AN15: 100000 | AO15: 100000 | AP15: 100000 | AQ15: 100000 | AR15: 100000 | AS15: 100000 | AT15: 100000 | AU15: 100000 | AV15: =SUM(X15:AI15) -> 0 | AW15: =SUM(AJ15:AU15) -> 1200000 | AX15: =$K15*(1+$L15) -> 1968000 | AY15: =AX15*(1+$M15) -> 2558400 | AZ15: =AY15*(1+$N15) -> 3070080 | BA15: =SUM(AV15:AZ15) -> 8796480
A16: 7 | B16: 대만 | C16: 동남아·APAC | D16: Little Loft(대만, 베이비) | E16: 베이비 | F16: 총판 | G16: 계약 | H16: A 계약·기존 거래 | I16: BABY | J16: M | K16: =AW16 -> 100000 | L16: 1.6 | M16: 0.8 | N16: 0.48 | V16: 거래처 매출표 | X16: 0 | Y16: 0 | Z16: 0 | AA16: 0 | AB16: 15004 | AC16: 15946 | AD16: 0 | AE16: 0 | AF16: 0 | AG16: 0 | AH16: 20000 | AI16: 0 | AJ16: 4781 | AK16: 5241 | AL16: 5746 | AM16: 6299 | AN16: 6906 | AO16: 7572 | AP16: 8301 | AQ16: 9100 | AR16: 9977 | AS16: 10938 | AT16: 11992 | AU16: 13147 | AV16: =SUM(X16:AI16) -> 50950 | AW16: =SUM(AJ16:AU16) -> 100000 | AX16: =$K16*(1+$L16) -> 260000 | AY16: =AX16*(1+$M16) -> 468000 | AZ16: =AY16*(1+$N16) -> 692640 | BA16: =SUM(AV16:AZ16) -> 1571590
A17: 8 | B17: 태국 | C17: 동남아·APAC | D17: Punnita House(태국, 베이비) | E17: 베이비 | F17: 총판 | G17: 계약 | H17: A 계약·기존 거래 | I17: BABY | J17: M | K17: =AW17 -> 120000 | L17: 1.6 | M17: 0.8 | N17: 0.48 | V17: 거래처 매출표 · USD 30,000 발주: 2026-12 선금 50%(2,000만원) + 잔금 50%(2,000만원)는 2027-01에 반영(잔금 수령월은 가정) | X17: 0 | Y17: 0 | Z17: 22595 | AA17: 0 | AB17: 0 | AC17: 23287 | AD17: 0 | AE17: 0 | AF17: 0 | AG17: 0 | AH17: 0 | AI17: 20000 | AJ17: 20000 | AK17: 0 | AL17: 6386 | AM17: 7001 | AN17: 7676 | AO17: 8415 | AP17: 9225 | AQ17: 10114 | AR17: 11088 | AS17: 12156 | AT17: 13327 | AU17: 14612 | AV17: =SUM(X17:AI17) -> 65882 | AW17: =SUM(AJ17:AU17) -> 120000 | AX17: =$K17*(1+$L17) -> 312000 | AY17: =AX17*(1+$M17) -> 561600 | AZ17: =AY17*(1+$N17) -> 831168 | BA17: =SUM(AV17:AZ17) -> 1890650
A18: 9 | B18: 미정 | C18: 동남아·APAC | D18: 신규 거래선-1 Swara Baby(베이비) | E18: 베이비 | F18: 총판 | G18: 진행 중 | H18: B 등록·입찰·협의 단계 | I18: BABY | J18: M | K18: =AW18 -> 100000 | L18: 1.6 | M18: 0.8 | N18: 0.48 | V18: 거래처 매출표 · 2027 신규 | X18: 0 | Y18: 0 | Z18: 0 | AA18: 0 | AB18: 0 | AC18: 0 | AD18: 0 | AE18: 0 | AF18: 0 | AG18: 0 | AH18: 0 | AI18: 0 | AJ18: 4781 | AK18: 5241 | AL18: 5746 | AM18: 6299 | AN18: 6906 | AO18: 7572 | AP18: 8301 | AQ18: 9100 | AR18: 9977 | AS18: 10938 | AT18: 11992 | AU18: 13147 | AV18: =SUM(X18:AI18) -> 0 | AW18: =SUM(AJ18:AU18) -> 100000 | AX18: =$K18*(1+$L18) -> 260000 | AY18: =AX18*(1+$M18) -> 468000 | AZ18: =AY18*(1+$N18) -> 692640 | BA18: =SUM(AV18:AZ18) -> 1520640
A19: 10 | B19: 미정 | C19: 동남아·APAC | D19: 신규 거래선-2(베이비) | E19: 베이비 | F19: 총판 | G19: 진행 중 | H19: B 등록·입찰·협의 단계 | I19: BABY | J19: M | K19: =AW19 -> 80000 | L19: 1.6 | M19: 0.8 | N19: 0.48 | V19: 거래처 매출표 · 2027 신규 | X19: 0 | Y19: 0 | Z19: 0 | AA19: 0 | AB19: 0 | AC19: 0 | AD19: 0 | AE19: 0 | AF19: 0 | AG19: 0 | AH19: 0 | AI19: 0 | AJ19: 0 | AK19: 4403 | AL19: 4828 | AM19: 5293 | AN19: 5802 | AO19: 6361 | AP19: 6974 | AQ19: 7646 | AR19: 8382 | AS19: 9190 | AT19: 10075 | AU19: 11046 | AV19: =SUM(X19:AI19) -> 0 | AW19: =SUM(AJ19:AU19) -> 80000 | AX19: =$K19*(1+$L19) -> 208000 | AY19: =AX19*(1+$M19) -> 374400 | AZ19: =AY19*(1+$N19) -> 554112 | BA19: =SUM(AV19:AZ19) -> 1216512
A20: 11 | B20: 한국 | C20: 한국 | D20: 삼성노블카운티 | E20: 엘더리 | F20: 기관(직접) | G20: 계약 | H20: A 계약·기존 거래 | I20: SUB | J20: M | K20: =AW20 -> 94800 | L20: 0.32 | M20: 0.15 | N20: 0.08 | V20: 거래처 매출표 · 요양시설 레퍼런스(IR p.10) | X20: 0 | Y20: 0 | Z20: 0 | AA20: 0 | AB20: 0 | AC20: 0 | AD20: 0 | AE20: 0 | AF20: 0 | AG20: 0 | AH20: 7900 | AI20: 7900 | AJ20: 7900 | AK20: 7900 | AL20: 7900 | AM20: 7900 | AN20: 7900 | AO20: 7900 | AP20: 7900 | AQ20: 7900 | AR20: 7900 | AS20: 7900 | AT20: 7900 | AU20: 7900 | AV20: =SUM(X20:AI20) -> 15800 | AW20: =SUM(AJ20:AU20) -> 94800 | AX20: =$K20*(1+$L20) -> 125136 | AY20: =AX20*(1+$M20) -> 143906.4 | AZ20: =AY20*(1+$N20) -> 155418.91 | BA20: =SUM(AV20:AZ20) -> 535061.31
A21: 12 | B21: 한국 | C21: 한국 | D21: 국내 요양병원·시설 구독 매출 | E21: 엘더리 | F21: 총판 | G21: 진행 중 | H21: B 등록·입찰·협의 단계 | I21: SUB | J21: M | K21: =AW21 -> 1986200 | L21: 1.44 | M21: 0.7 | N21: 0.4 | V21: 거래처 매출표 · IR p.10 요양시설 기저귀 유통사 경유 | X21: 0 | Y21: 0 | Z21: 0 | AA21: 0 | AB21: 0 | AC21: 0 | AD21: 0 | AE21: 0 | AF21: 0 | AG21: 0 | AH21: 22120 | AI21: 41080 | AJ21: 104676 | AK21: 115144 | AL21: 125612 | AM21: 136079 | AN21: 146547 | AO21: 167482 | AP21: 177950 | AQ21: 177950 | AR21: 188417 | AS21: 204980 | AT21: 215448 | AU21: 225915 | AV21: =SUM(X21:AI21) -> 63200 | AW21: =SUM(AJ21:AU21) -> 1986200 | AX21: =$K21*(1+$L21) -> 4846328 | AY21: =AX21*(1+$M21) -> 8238757.6 | AZ21: =AY21*(1+$N21) -> 11534261 | BA21: =SUM(AV21:AZ21) -> 26668746
... A30: 21 | B30: 인도 | C30: 인도 | D30: 케랄라 주정부(인도) | E30: 엘더리 | F30: 기타 | G30: 기존 | H30: A 계약·기존 거래 | I30: DIST | J30: M | K30: =AW30 -> 60000 | L30: 0 | M30: 0 | N30: 0 | V30: 거래처 매출표 | X30: 0 | Y30: 0 | Z30: 0 | AA30: 0 | AB30: 0 | AC30: 0 | AD30: 0 | AE30: 0 | AF30: 0 | AG30: 0 | AH30: 0 | AI30: 0 | AJ30: 0 | AK30: 0 | AL30: 0 | AM30: 0 | AN30: 0 | AO30: 0 | AP30: 0 | AQ30: 9900 | AR30: 10854 | AS30: 11899 | AT30: 13045 | AU30: 14302 | AV30: =SUM(X30:AI30) -> 0 | AW30: =SUM(AJ30:AU30) -> 60000 | AX30: =$K30*(1+$L30) -> 60000 | AY30: =AX30*(1+$M30) -> 60000 | AZ30: =AY30*(1+$N30) -> 60000 | BA30: =SUM(AV30:AZ30) -> 240000
A31: 22 | B31: 인도 | C31: 인도 | D31: 인도 뉴델리 디스트리뷰터 | E31: 엘더리 | F31: 총판 | G31: 진행 중 | H31: B 등록·입찰·협의 단계 | I31: DIST | J31: N | K31: =AW31 -> 60000 | V31: 거래처 매출표 · 인도 신규 디스트리뷰터(2026-12 초도, 2027 연간 발주), 2028~30 연간 입력값 | X31: 0 | Y31: 0 | Z31: 0 | AA31: 0 | AB31: 0 | AC31: 0 | AD31: 0 | AE31: 0 | AF31: 0 | AG31: 0 | AH31: 0 | AI31: 20000 | AJ31: 0 | AK31: 0 | AL31: 3832 | AM31: 4201 | AN31: 4605 | AO31: 5049 | AP31: 5535 | AQ31: 6068 | AR31: 6653 | AS31: 7294 | AT31: 7996 | AU31: 8767 | AV31: =SUM(X31:AI31) -> 20000 | AW31: =SUM(AJ31:AU31) -> 60000 | AX31: 200000 | AY31: 600000 | AZ31: 1000000 | BA31: =SUM(AV31:AZ31) -> 1880000
A32: 23 | B32: 인도 | C32: 인도 | D32: 인도 뭄바이 디스트리뷰터 | E32: 엘더리 | F32: 총판 | G32: 진행 중 | H32: B 등록·입찰·협의 단계 | I32: DIST | J32: N | K32: =AW32 -> 80000 | V32: 거래처 매출표 · 인도 신규 디스트리뷰터(2027 연간 발주), 2028~30 연간 입력값 | X32: 0 | Y32: 0 | Z32: 0 | AA32: 0 | AB32: 0 | AC32: 0 | AD32: 0 | AE32: 0 | AF32: 0 | AG32: 0 | AH32: 0 | AI32: 0 | AJ32: 3825 | AK32: 4193 | AL32: 4597 | AM32: 5040 | AN32: 5525 | AO32: 6057 | AP32: 6641 | AQ32: 7280 | AR32: 7982 | AS32: 8750 | AT32: 9593 | AU32: 10517 | AV32: =SUM(X32:AI32) -> 0 | AW32: =SUM(AJ32:AU32) -> 80000 | AX32: 200000 | AY32: 600000 | AZ32: 1000000 | BA32: =SUM(AV32:AZ32) -> 1880000
A33: 24 | B33: 네덜란드 | C33: 유럽 | D33: GISI Distribution(네덜란드·룩셈부르크·독일·폴란드) | E33: 엘더리 | F33: 총판 | G33: 계약 | H33: A 계약·기존 거래 | I33: DIST | J33: M | K33: =AW33 -> 150000 | L33: 1.6 | M33: 0.8 | N33: 0.48 | V33: 거래처 매출표 · 2026-09 €24,000(매출표 환산 31,303천원) 포함 · IR p.23 · IR p.25 표기 GIV | X33: 0 | Y33: 0 | Z33: 6359 | AA33: 0 | AB33: 0 | AC33: 0 | AD33: 0 | AE33: 0 | AF33: 31303 | AG33: 16000 | AH33: 0 | AI33: 16000 | AJ33: 7171 | AK33: 7862 | AL33: 8619 | AM33: 9449 | AN33: 10359 | AO33: 11357 | AP33: 12451 | AQ33: 13651 | AR33: 14966 | AS33: 16407 | AT33: 17988 | AU33: 19720 | AV33: =SUM(X33:AI33) -> 69662 | AW33: =SUM(AJ33:AU33) -> 150000 | AX33: =$K33*(1+$L33) -> 390000 | AY33: =AX33*(1+$M33) -> 702000 | AZ33: =AY33*(1+$N33) -> 1038960 | BA33: =SUM(AV33:AZ33) -> 2350622
A34: 25 | B34: 폴란드 | C34: 유럽 | D34: NEUCA(폴란드 총판) | E34: 엘더리 | F34: 총판 | G34: 접촉 | H34: B 등록·입찰·협의 단계 | I34: DIST | J34: M | K34: =AW34 -> 150000 | L34: 1.6 | M34: 0.8 | N34: 0.48 | V34: 거래처 매출표 · 폴란드 총판 | X34: 0 | Y34: 0 | Z34: 0 | AA34: 0 | AB34: 0 | AC34: 0 | AD34: 0 | AE34: 0 | AF34: 0 | AG34: 0 | AH34: 0 | AI34: 0 | AJ34: 0 | AK34: 8256 | AL34: 9052 | AM34: 9924 | AN34: 10880 | AO34: 11928 | AP34: 13076 | AQ34: 14336 | AR34: 15717 | AS34: 17231 | AT34: 18891 | AU34: 20709 | AV34: =SUM(X34:AI34) -> 0 | AW34: =SUM(AJ34:AU34) -> 150000 | AX34: =$K34*(1+$L34) -> 390000 | AY34: =AX34*(1+$M34) -> 702000 | AZ34: =AY34*(1+$N34) -> 1038960 | BA34: =SUM(AV34:AZ34) -> 2280960
A35: 26 | B35: 독일 | C35: 유럽 | D35: Armedion(독일 총판) | E35: 엘더리 | F35: 총판 | G35: 진행 중 | H35: B 등록·입찰·협의 단계 | I35: DIST | J35: M | K35: =AW35 -> 150000 | L35: 1.6 | M35: 0.8 | N35: 0.48 | V35: 거래처 매출표 | X35: 0 | Y35: 0 | Z35: 0 | AA35: 0 | AB35: 0 | AC35: 0 | AD35: 0 | AE35: 0 | AF35: 0 | AG35: 0 | AH35: 0 | AI35: 50000 | AJ35: 0 | AK35: 0 | AL35: 0 | AM35: 0 | AN35: 13293 | AO35: 14573 | AP35: 15977 | AQ35: 17516 | AR35: 19203 | AS35: 21053 | AT35: 23081 | AU35: 25304 | AV35: =SUM(X35:AI35) -> 50000 | AW35: =SUM(AJ35:AU35) -> 150000 | AX35: =$K35*(1+$L35) -> 390000 | AY35: =AX35*(1+$M35) -> 702000 | AZ35: =AY35*(1+$N35) -> 1038960 | BA35: =SUM(AV35:AZ35) -> 2330960
A36: 27 | B36: 싱가포르 | C36: 동남아·APAC | D36: INTEGA(싱가포르·말레이시아·태국) | E36: 엘더리 | F36: 총판 | G36: 계약 | H36: A 계약·기존 거래 | I36: DIST | J36: M | K36: =AW36 -> 300000 | L36: 1.28 | M36: 0.6 | N36: 0.4 | V36: 거래처 매출표 · IR p.23 | X36: 12879 | Y36: 0 | Z36: 13042 | AA36: 0 | AB36: 0 | AC36: 0 | AD36: 0 | AE36: 0 | AF36: 0 | AG36: 0 | AH36: 23625 | AI36: 0 | AJ36: 0 | AK36: 16513 | AL36: 18103 | AM36: 19847 | AN36: 21759 | AO36: 23855 | AP36: 26153 | AQ36: 28672 | AR36: 31434 | AS36: 34462 | AT36: 37781 | AU36: 41421 | AV36: =SUM(X36:AI36) -> 49546 | AW36: =SUM(AJ36:AU36) -> 300000 | AX36: =$K36*(1+$L36) -> 684000 | AY36: =AX36*(1+$M36) -> 1094400 | AZ36: =AY36*(1+$N36) -> 1532160 | BA36: =SUM(AV36:AZ36) -> 3660106
A37: 28 | B37: 말레이시아 | C37: 동남아·APAC | D37: Sunway Sanctuary(말레이시아) | E37: 엘더리 | F37: 기관(직접) | G37: PoC / R&D | H37: B 등록·입찰·협의 단계 | I37: RND | J37: M | K37: =AW37 -> 50000 | L37: 3.2 | M37: 1 | N37: 0.4 | V37: 거래처 매출표 · IR p.31 PoC/R&D → 상용 전환 가정 | X37: 0 | Y37: 0 | Z37: 0 | AA37: 0 | AB37: 0 | AC37: 0 | AD37: 0 | AE37: 0 | AF37: 0 | AG37: 0 | AH37: 0 | AI37: 0 | AJ37: 0 | AK37: 0 | AL37: 0 | AM37: 3739 | AN37: 4100 | AO37: 4494 | AP37: 4927 | AQ37: 5402 | AR37: 5922 | AS37: 6493 | AT37: 7118 | AU37: 7805 | AV37: =SUM(X37:AI37) -> 0 | AW37: =SUM(AJ37:AU37) -> 50000 | AX37: =$K37*(1+$L37) -> 210000 | AY37: =AX37*(1+$M37) -> 420000 | AZ37: =AY37*(1+$N37) -> 588000 | BA37: =SUM(AV37:AZ37) -> 1268000
A38: 29 | B38: 싱가포르 | C38: 동남아·APAC | D38: NHG(KTPH·TTSH·Woodlands) 스마트 병동 | E38: 엘더리 | F38: 기관(직접) | G38: 단독입찰 제안(LOA 대기) | H38: B 등록·입찰·협의 단계 | I38: HWPROJ | J38: M | K38: =AW38 -> 400000 | L38: 0.8 | M38: 0.4 | N38: 0.32 | V38: 거래처 매출표 · 2026-12 KTPH SGD 180,000, 2027 NHG 4억 · 단독입찰 제안(LOA 대기) | X38: 0 | Y38: 0 | Z38: 0 | AA38: 0 | AB38: 0 | AC38: 0 | AD38: 0 | AE38: 0 | AF38: 0 | AG38: 0 | AH38: 0 | AI38: 188957 | AJ38: 30000 | AK38: 30000 | AL38: 30000 | AM38: 30000 | AN38: 30000 | AO38: 30000 | AP38: 30000 | AQ38: 30000 | AR38: 30000 | AS38: 30000 | AT38: 50000 | AU38: 50000 | AV38: =SUM(X38:AI38) -> 188957 | AW38: =SUM(AJ38:AU38) -> 400000 | AX38: =$K38*(1+$L38) -> 720000 | AY38: =AX38*(1+$M38) -> 1008000 | AZ38: =AY38*(1+$N38) -> 1330560 | BA38: =SUM(AV38:AZ38) -> 3647517
A39: 30 | B39: 싱가포르 | C39: 동남아·APAC | D39: IMH 스마트 욕창 케어 R&D | E39: 엘더리 | F39: 기관(직접) | G39: 계약 | H39: A 계약·기존 거래 | I39: RND | J39: M | K39: =AW39 -> 180000 | L39: 0 | M39: 0 | N39: 0 | V39: 거래처 매출표 · SGD 45,000을 2026-10·11월 50%씩 분할(각 23,625천원) · IR p.20 | X39: 0 | Y39: 0 | Z39: 0 | AA39: 0 | AB39: 0 | AC39: 0 | AD39: 0 | AE39: 0 | AF39: 0 | AG39: 23625 | AH39: 23625 | AI39: 0 | AJ39: 0 | AK39: 0 | AL39: 11495 | AM39: 12602 | AN39: 13816 | AO39: 15147 | AP39: 16606 | AQ39: 18205 | AR39: 19959 | AS39: 21881 | AT39: 23989 | AU39: 26300 | AV39: =SUM(X39:AI39) -> 47250 | AW39: =SUM(AJ39:AU39) -> 180000 | AX39: =$K39*(1+$L39) -> 180000 | AY39: =AX39*(1+$M39) -> 180000 | AZ39: =AY39*(1+$N39) -> 180000 | BA39: =SUM(AV39:AZ39) -> 767250
A40: 31 | B40: 호주 | C40: 동남아·APAC | D40: Healthbeats(호주·뉴질랜드) | E40: 엘더리 | F40: 총판 | G40: 계약 | H40: A 계약·기존 거래 | I40: DIST | J40: M | K40: =AW40 -> 300000 | L40: 1.6 | M40: 0.8 | N40: 0.48 | V40: 거래처 매출표 · IR p.23 | X40: 0 | Y40: 0 | Z40: 0 | AA40: 0 | AB40: 0 | AC40: 0 | AD40: 0 | AE40: 0 | AF40: 1903 | AG40: 0 | AH40: 0 | AI40: 0 | AJ40: 0 | AK40: 0 | AL40: 0 | AM40: 22436 | AN40: 24597 | AO40: 26967 | AP40: 29564 | AQ40: 32412 | AR40: 35534 | AS40: 38957 | AT40: 42709 | AU40: 46824 | AV40: =SUM(X40:AI40) -> 1903 | AW40: =SUM(AJ40:AU40) -> 300000 | AX40: =$K40*(1+$L40) -> 780000 | AY40: =AX40*(1+$M40) -> 1404000 | AZ40: =AY40*(1+$N40) -> 2077920 | BA40: =SUM(AV40:AZ40) -> 4563823
A41: 32 | B41: 일본 | C41: 일본 | D41: 일본 신규 시설·재가 채널(하트키움·TAIS 외 직접 도입) | E41: 엘더리 | F41: 신규 파이프라인 | G41: 신규 | H41: C 신규 파이프라인(미확정) | I41: COH | J41: C | K41: =AW41 -> 0 | V41: 오사카 외 간사이·수도권 시설 확대, 介護テクノロジー導入支援 연계(가정) · 2028~30 = 지역 목표(IR p.24 차트 비중, 8_가정 §2b) − 같은 지역 지정 거래처 | X41: 0 | Y41: 0 | Z41: 0 | AA41: 0 | AB41: 0 | AC41: 0 | AD41: 0 | AE41: 0 | AF41: 0 | AG41: 0 | AH41: 0 | AI41: 0 | AJ41: 0 | AK41: 0 | AL41: 0 | AM41: 0 | AN41: 0 | AO41: 0 | AP41: 0 | AQ41: 0 | AR41: 0 | AS41: 0 | AT41: 0 | AU41: 0 | AV41: =SUM(X41:AI41) -> 0 | AW41: =SUM(AJ41:AU41) -> 0 | AX41: =('8_가정'!$E$6*(1-'8_가정'!$E$33)-SUMIF($C$10:$C$40,"한국",AX$10:AX$40)-SUMIF($C$10:$C$40,"인도",AX$10:AX$40))*'8_가정'!$E$28/('8_가정'!$E$28+'8_가정'!$E$29+'8_가정'!$E$30+'8_가정'!$E$31)-SUMIF($C$10:$C$40,$C41,AX$10:AX$40) -> 7327668 | AY41: =('8_가정'!$F$6*(1-'8_가정'!$F$33)-SUMIF($C$10:$C$40,"한국",AY$10:AY$40)-SUMIF($C$10:$C$40,"인도",AY$10:AY$40))*'8_가정'!$F$28/('8_가정'!$F$28+'8_가정'!$F$29+'8_가정'!$F$30+'8_가정'!$F$31)-SUMIF($C$10:$C$40,$C41,AY$10:AY$40) -> 25659508 | AZ41: =('8_가정'!$G$6*(1-'8_가정'!$G$33)-SUMIF($C$10:$C$40,"한국",AZ$10:AZ$40)-SUMIF($C$10:$C$40,"인도",AZ$10:AZ$40))*'8_가정'!$G$28/('8_가정'!$G$28+'8_가정'!$G$29+'8_가정'!$G$30+'8_가정'!$G$31)-SUMIF($C$10:$C$40,$C41,AZ$10:AZ$40) -> 55068542 | BA41: =SUM(AV41:AZ41) -> 88055718
A42: 33 | B42: 싱가포르·말레이시아 외 | C42: 동남아·APAC | D42: 동남아 병원·요양그룹 확대(IHH·NTUC·SingHealth·Econ·ACG 전환) | E42: 엘더리 | F42: 신규 파이프라인 | G42: 신규 | H42: C 신규 파이프라인(미확정) | I42: COH | J42: C | K42: =AW42 -> 162400 | V42: IR p.19·25·29~32: PoC·구매절차 준비 중인 대형 그룹의 상용 전환(가정) · 2028~30 = 지역 목표(IR p.24 차트 비중, 8_가정 §2b) − 같은 지역 지정 거래처 | X42: 0 | Y42: 0 | Z42: 0 | AA42: 0 | AB42: 0 | AC42: 0 | AD42: 0 | AE42: 0 | AF42: 0 | AG42: 0 | AH42: 0 | AI42: 0 | AJ42: 0 | AK42: 0 | AL42: 16240 | AM42: 16240 | AN42: 16240 | AO42: 16240 | AP42: 16240 | AQ42: 16240 | AR42: 16240 | AS42: 16240 | AT42: 16240 | AU42: 16240 | AV42: =SUM(X42:AI42) -> 0 | AW42: =SUM(AJ42:AU42) -> 162400 | AX42: =('8_가정'!$E$6*(1-'8_가정'!$E$33)-SUMIF($C$10:$C$40,"한국",AX$10:AX$40)-SUMIF($C$10:$C$40,"인도",AX$10:AX$40))*'8_가정'!$E$30/('8_가정'!$E$28+'8_가정'!$E$29+'8_가정'!$E$30+'8_가정'!$E$31)-SUMIF($C$10:$C$40,$C42,AX$10:AX$40) -> 237185.52 | AY42: =('8_가정'!$F$6*(1-'8_가정'!$F$33)-SUMIF($C$10:$C$40,"한국",AY$10:AY$40)-SUMIF($C$10:$C$40,"인도",AY$10:AY$40))*'8_가정'!$F$30/('8_가정'!$F$28+'8_가정'!$F$29+'8_가정'!$F$30+'8_가정'!$F$31)-SUMIF($C$10:$C$40,$C42,AY$10:AY$40) -> 1332035.3 | AZ42: =('8_가정'!$G$6*(1-'8_가정'!$G$33)-SUMIF($C$10:$C$40,"한국",AZ$10:AZ$40)-SUMIF($C$10:$C$40,"인도",AZ$10:AZ$40))*'8_가정'!$G$30/('8_가정'!$G$28+'8_가정'!$G$29+'8_가정'!$G$30+'8_가정'!$G$31)-SUMIF($C$10:$C$40,$C42,AZ$10:AZ$40) -> 6720808.1 | BA42: =SUM(AV42:AZ42) -> 8452428.9
A43: 34 | B43: 유럽 | C43: 유럽 | D43: 유럽 총판 확대(NL·DE·PL·PT·북유럽) | E43: 엘더리 | F43: 신규 파이프라인 | G43: 신규 | H43: C 신규 파이프라인(미확정) | I43: COH | J43: C | K43: =AW43 -> 389760 | V43: IR p.24 로드맵 2027 EU PoC → 2028~ 유럽 확대(가정). 2028~30 = 유럽 지역 목표(8_가정 §2b) − 지정 유럽 총판(GISI·NEUCA·Armedion). 2028은 지정 총판 성장분이 커서 본 행은 일시 감소 | X43: 0 | Y43: 0 | Z43: 0 | AA43: 0 | AB43: 0 | AC43: 0 | AD43: 0 | AE43: 0 | AF43: 0 | AG43: 0 | AH43: 0 | AI43: 0 | AJ43: 16240 | AK43: 16240 | AL43: 16240 | AM43: 16240 | AN43: 32480 | AO43: 32480 | AP43: 32480 | AQ43: 32480 | AR43: 48720 | AS43: 48720 | AT43: 48720 | AU43: 48720 | AV43: =SUM(X43:AI43) -> 0 | AW43: =SUM(AJ43:AU43) -> 389760 | AX43: =('8_가정'!$E$6*(1-'8_가정'!$E$33)-SUMIF($C$10:$C$40,"한국",AX$10:AX$40)-SUMIF($C$10:$C$40,"인도",AX$10:AX$40))*'8_가정'!$E$31/('8_가정'!$E$28+'8_가정'!$E$29+'8_가정'!$E$30+'8_가정'!$E$31)-SUMIF($C$10:$C$40,$C43,AX$10:AX$40) -> 345892.17 | AY43: =('8_가정'!$F$6*(1-'8_가정'!$F$33)-SUMIF($C$10:$C$40,"한국",AY$10:AY$40)-SUMIF($C$10:$C$40,"인도",AY$10:AY$40))*'8_가정'!$F$31/('8_가정'!$F$28+'8_가정'!$F$29+'8_가정'!$F$30+'8_가정'!$F$31)-SUMIF($C$10:$C$40,$C43,AY$10:AY$40) -> 4183124.5 | AZ43: =('8_가정'!$G$6*(1-'8_가정'!$G$33)-SUMIF($C$10:$C$40,"한국",AZ$10:AZ$40)-SUMIF($C$10:$C$40,"인도",AZ$10:AZ$40))*'8_가정'!$G$31/('8_가정'!$G$28+'8_가정'!$G$29+'8_가정'!$G$30+'8_가정'!$G$31)-SUMIF($C$10:$C$40,$C43,AZ$10:AZ$40) -> 9968344.4 | BA43: =SUM(AV43:AZ43) -> 14887121
